[2023-04-24 18:53:06,967: INFO/MainProcess] Connected to redis://default:**@containers-us-west-97.railway.app:5950//
[2023-04-24 18:53:07,188: INFO/SpawnPoolWorker-1] child process 21092 calling self.run()
[2023-04-24 18:53:07,188: INFO/SpawnPoolWorker-2] child process 13876 calling self.run()
[2023-04-24 18:53:07,204: INFO/SpawnPoolWorker-3] child process 21688 calling self.run()
[2023-04-24 18:53:07,219: INFO/SpawnPoolWorker-6] child process 7472 calling self.run()
[2023-04-24 18:53:07,219: INFO/SpawnPoolWorker-4] child process 16056 calling self.run()
[2023-04-24 18:53:07,219: INFO/SpawnPoolWorker-10] child process 7376 calling self.run()
[2023-04-24 18:53:07,237: INFO/SpawnPoolWorker-5] child process 21100 calling self.run()
[2023-04-24 18:53:07,237: INFO/SpawnPoolWorker-9] child process 16172 calling self.run()
[2023-04-24 18:53:07,251: INFO/SpawnPoolWorker-7] child process 9448 calling self.run()
[2023-04-24 18:53:07,267: INFO/SpawnPoolWorker-11] child process 7584 calling self.run()
[2023-04-24 18:53:07,300: INFO/SpawnPoolWorker-12] child process 12980 calling self.run()
[2023-04-24 18:53:07,300: INFO/SpawnPoolWorker-8] child process 20964 calling self.run()
[2023-04-24 18:53:07,455: INFO/MainProcess] mingle: searching for neighbors
[2023-04-24 18:53:09,923: INFO/MainProcess] mingle: all alone
[2023-04-24 18:53:11,190: WARNING/MainProcess] C:\Users\User\AppData\Local\Programs\Python\Python311\Lib\site-packages\celery\fixups\django.py:203: UserWarning: Using settings.DEBUG leads to a memory
            leak, never use this setting in production environments!
  warnings.warn('''Using settings.DEBUG leads to a memory

[2023-04-24 18:53:11,190: INFO/MainProcess] celery@DESKTOP-LEVDR36 ready.
[2023-04-24 18:53:11,364: INFO/MainProcess] Task base.tasks.send_the_email[9acded01-feaa-41af-a1d3-2d8b8cc6b840] received
[2023-04-24 18:53:11,374: WARNING/MainProcess] --- Logging error ---
[2023-04-24 18:53:11,375: WARNING/MainProcess] Traceback (most recent call last):
[2023-04-24 18:53:11,375: WARNING/MainProcess]   File "C:\Users\User\AppData\Local\Programs\Python\Python311\Lib\logging\__init__.py", line 1110, in emit
    msg = self.format(record)
          ^^^^^^^^^^^^^^^^^^^
[2023-04-24 18:53:11,375: WARNING/MainProcess]   File "C:\Users\User\AppData\Local\Programs\Python\Python311\Lib\logging\__init__.py", line 953, in format
    return fmt.format(record)
           ^^^^^^^^^^^^^^^^^^
[2023-04-24 18:53:11,375: WARNING/MainProcess]   File "C:\Users\User\AppData\Local\Programs\Python\Python311\Lib\site-packages\celery\utils\log.py", line 146, in format
    msg = super().format(record)
          ^^^^^^^^^^^^^^^^^^^^^^
[2023-04-24 18:53:11,375: WARNING/MainProcess]   File "C:\Users\User\AppData\Local\Programs\Python\Python311\Lib\logging\__init__.py", line 695, in format
    record.exc_text = self.formatException(record.exc_info)
                      ^^^^^^^^^^^^^^^^^^^^^^^^^^^^^^^^^^^^^
[2023-04-24 18:53:11,375: WARNING/MainProcess]   File "C:\Users\User\AppData\Local\Programs\Python\Python311\Lib\site-packages\celery\utils\log.py", line 142, in formatException
    r = super().formatException(ei)
        ^^^^^^^^^^^^^^^^^^^^^^^^^^^
[2023-04-24 18:53:11,375: WARNING/MainProcess]   File "C:\Users\User\AppData\Local\Programs\Python\Python311\Lib\logging\__init__.py", line 645, in formatException
    traceback.print_exception(ei[0], ei[1], tb, None, sio)
[2023-04-24 18:53:11,375: WARNING/MainProcess]   File "C:\Users\User\AppData\Local\Programs\Python\Python311\Lib\traceback.py", line 124, in print_exception
    te = TracebackException(type(value), value, tb, limit=limit, compact=True)
         ^^^^^^^^^^^^^^^^^^^^^^^^^^^^^^^^^^^^^^^^^^^^^^^^^^^^^^^^^^^^^^^^^^^^^
[2023-04-24 18:53:11,375: WARNING/MainProcess]   File "C:\Users\User\AppData\Local\Programs\Python\Python311\Lib\traceback.py", line 690, in __init__
    self.stack = StackSummary._extract_from_extended_frame_gen(
                 ^^^^^^^^^^^^^^^^^^^^^^^^^^^^^^^^^^^^^^^^^^^^^^
[2023-04-24 18:53:11,375: WARNING/MainProcess]   File "C:\Users\User\AppData\Local\Programs\Python\Python311\Lib\traceback.py", line 416, in _extract_from_extended_frame_gen
    for f, (lineno, end_lineno, colno, end_colno) in frame_gen:
[2023-04-24 18:53:11,375: WARNING/MainProcess]   File "C:\Users\User\AppData\Local\Programs\Python\Python311\Lib\traceback.py", line 353, in _walk_tb_with_full_positions
    positions = _get_code_position(tb.tb_frame.f_code, tb.tb_lasti)
                ^^^^^^^^^^^^^^^^^^^^^^^^^^^^^^^^^^^^^^^^^^^^^^^^^^^
[2023-04-24 18:53:11,375: WARNING/MainProcess]   File "C:\Users\User\AppData\Local\Programs\Python\Python311\Lib\traceback.py", line 366, in _get_code_position
    positions_gen = code.co_positions()
                    ^^^^^^^^^^^^^^^^^
[2023-04-24 18:53:11,375: WARNING/MainProcess] AttributeError: '_Code' object has no attribute 'co_positions'
[2023-04-24 18:53:11,375: WARNING/MainProcess] Call stack:
[2023-04-24 18:53:11,375: WARNING/MainProcess]   File "C:\Users\User\AppData\Local\Programs\Python\Python311\Lib\threading.py", line 995, in _bootstrap
    self._bootstrap_inner()
[2023-04-24 18:53:11,375: WARNING/MainProcess]   File "C:\Users\User\AppData\Local\Programs\Python\Python311\Lib\threading.py", line 1038, in _bootstrap_inner
    self.run()
[2023-04-24 18:53:11,375: WARNING/MainProcess]   File "C:\Users\User\AppData\Local\Programs\Python\Python311\Lib\site-packages\billiard\pool.py", line 504, in run
    return self.body()
[2023-04-24 18:53:11,375: WARNING/MainProcess]   File "C:\Users\User\AppData\Local\Programs\Python\Python311\Lib\site-packages\billiard\pool.py", line 899, in body
    for _ in self._process_result(1.0):  # blocking
[2023-04-24 18:53:11,375: WARNING/MainProcess]   File "C:\Users\User\AppData\Local\Programs\Python\Python311\Lib\site-packages\billiard\pool.py", line 878, in _process_result
    on_state_change(task)
[2023-04-24 18:53:11,375: WARNING/MainProcess]   File "C:\Users\User\AppData\Local\Programs\Python\Python311\Lib\site-packages\billiard\pool.py", line 853, in on_state_change
    state_handlers[state](*args)
[2023-04-24 18:53:11,375: WARNING/MainProcess]   File "C:\Users\User\AppData\Local\Programs\Python\Python311\Lib\site-packages\billiard\pool.py", line 835, in on_ready
    item._set(i, obj)
[2023-04-24 18:53:11,375: WARNING/MainProcess]   File "C:\Users\User\AppData\Local\Programs\Python\Python311\Lib\site-packages\billiard\pool.py", line 1828, in _set
    self.safe_apply_callback(
[2023-04-24 18:53:11,375: WARNING/MainProcess]   File "C:\Users\User\AppData\Local\Programs\Python\Python311\Lib\site-packages\billiard\pool.py", line 1796, in safe_apply_callback
    fun(*args, **kwargs)
[2023-04-24 18:53:11,375: WARNING/MainProcess]   File "C:\Users\User\AppData\Local\Programs\Python\Python311\Lib\site-packages\celery\worker\request.py", line 596, in on_failure
    error('Task handler raised error: %r', exc,
[2023-04-24 18:53:11,375: WARNING/MainProcess] Message: 'Task handler raised error: %r'
Arguments: (ValueError('not enough values to unpack (expected 3, got 0)'),)
[2023-04-24 18:53:11,515: INFO/MainProcess] Task base.tasks.send_the_email[fec00d41-3eb6-43db-ab9e-586ace6094f6] received
[2023-04-24 18:53:11,522: WARNING/MainProcess] --- Logging error ---
[2023-04-24 18:53:11,523: WARNING/MainProcess] Traceback (most recent call last):
[2023-04-24 18:53:11,524: WARNING/MainProcess]   File "C:\Users\User\AppData\Local\Programs\Python\Python311\Lib\logging\__init__.py", line 1110, in emit
    msg = self.format(record)
          ^^^^^^^^^^^^^^^^^^^
[2023-04-24 18:53:11,525: WARNING/MainProcess]   File "C:\Users\User\AppData\Local\Programs\Python\Python311\Lib\logging\__init__.py", line 953, in format
    return fmt.format(record)
           ^^^^^^^^^^^^^^^^^^
[2023-04-24 18:53:11,525: WARNING/MainProcess]   File "C:\Users\User\AppData\Local\Programs\Python\Python311\Lib\site-packages\celery\utils\log.py", line 146, in format
    msg = super().format(record)
          ^^^^^^^^^^^^^^^^^^^^^^
[2023-04-24 18:53:11,526: WARNING/MainProcess]   File "C:\Users\User\AppData\Local\Programs\Python\Python311\Lib\logging\__init__.py", line 695, in format
    record.exc_text = self.formatException(record.exc_info)
                      ^^^^^^^^^^^^^^^^^^^^^^^^^^^^^^^^^^^^^
[2023-04-24 18:53:11,526: WARNING/MainProcess]   File "C:\Users\User\AppData\Local\Programs\Python\Python311\Lib\site-packages\celery\utils\log.py", line 142, in formatException
    r = super().formatException(ei)
        ^^^^^^^^^^^^^^^^^^^^^^^^^^^
[2023-04-24 18:53:11,527: WARNING/MainProcess]   File "C:\Users\User\AppData\Local\Programs\Python\Python311\Lib\logging\__init__.py", line 645, in formatException
    traceback.print_exception(ei[0], ei[1], tb, None, sio)
[2023-04-24 18:53:11,527: WARNING/MainProcess]   File "C:\Users\User\AppData\Local\Programs\Python\Python311\Lib\traceback.py", line 124, in print_exception
    te = TracebackException(type(value), value, tb, limit=limit, compact=True)
         ^^^^^^^^^^^^^^^^^^^^^^^^^^^^^^^^^^^^^^^^^^^^^^^^^^^^^^^^^^^^^^^^^^^^^
[2023-04-24 18:53:11,527: WARNING/MainProcess]   File "C:\Users\User\AppData\Local\Programs\Python\Python311\Lib\traceback.py", line 690, in __init__
    self.stack = StackSummary._extract_from_extended_frame_gen(
                 ^^^^^^^^^^^^^^^^^^^^^^^^^^^^^^^^^^^^^^^^^^^^^^
[2023-04-24 18:53:11,528: WARNING/MainProcess]   File "C:\Users\User\AppData\Local\Programs\Python\Python311\Lib\traceback.py", line 416, in _extract_from_extended_frame_gen
    for f, (lineno, end_lineno, colno, end_colno) in frame_gen:
[2023-04-24 18:53:11,528: WARNING/MainProcess]   File "C:\Users\User\AppData\Local\Programs\Python\Python311\Lib\traceback.py", line 353, in _walk_tb_with_full_positions
    positions = _get_code_position(tb.tb_frame.f_code, tb.tb_lasti)
                ^^^^^^^^^^^^^^^^^^^^^^^^^^^^^^^^^^^^^^^^^^^^^^^^^^^
[2023-04-24 18:53:11,528: WARNING/MainProcess]   File "C:\Users\User\AppData\Local\Programs\Python\Python311\Lib\traceback.py", line 366, in _get_code_position
    positions_gen = code.co_positions()
                    ^^^^^^^^^^^^^^^^^
[2023-04-24 18:53:11,528: WARNING/MainProcess] AttributeError: '_Code' object has no attribute 'co_positions'
[2023-04-24 18:53:11,529: WARNING/MainProcess] Call stack:
[2023-04-24 18:53:11,529: WARNING/MainProcess]   File "C:\Users\User\AppData\Local\Programs\Python\Python311\Lib\threading.py", line 995, in _bootstrap
    self._bootstrap_inner()
[2023-04-24 18:53:11,529: WARNING/MainProcess]   File "C:\Users\User\AppData\Local\Programs\Python\Python311\Lib\threading.py", line 1038, in _bootstrap_inner
    self.run()
[2023-04-24 18:53:11,529: WARNING/MainProcess]   File "C:\Users\User\AppData\Local\Programs\Python\Python311\Lib\site-packages\billiard\pool.py", line 504, in run
    return self.body()
[2023-04-24 18:53:11,529: WARNING/MainProcess]   File "C:\Users\User\AppData\Local\Programs\Python\Python311\Lib\site-packages\billiard\pool.py", line 899, in body
    for _ in self._process_result(1.0):  # blocking
[2023-04-24 18:53:11,529: WARNING/MainProcess]   File "C:\Users\User\AppData\Local\Programs\Python\Python311\Lib\site-packages\billiard\pool.py", line 878, in _process_result
    on_state_change(task)
[2023-04-24 18:53:11,529: WARNING/MainProcess]   File "C:\Users\User\AppData\Local\Programs\Python\Python311\Lib\site-packages\billiard\pool.py", line 853, in on_state_change
    state_handlers[state](*args)
[2023-04-24 18:53:11,530: WARNING/MainProcess]   File "C:\Users\User\AppData\Local\Programs\Python\Python311\Lib\site-packages\billiard\pool.py", line 835, in on_ready
    item._set(i, obj)
[2023-04-24 18:53:11,530: WARNING/MainProcess]   File "C:\Users\User\AppData\Local\Programs\Python\Python311\Lib\site-packages\billiard\pool.py", line 1828, in _set
    self.safe_apply_callback(
[2023-04-24 18:53:11,530: WARNING/MainProcess]   File "C:\Users\User\AppData\Local\Programs\Python\Python311\Lib\site-packages\billiard\pool.py", line 1796, in safe_apply_callback
    fun(*args, **kwargs)
[2023-04-24 18:53:11,530: WARNING/MainProcess]   File "C:\Users\User\AppData\Local\Programs\Python\Python311\Lib\site-packages\celery\worker\request.py", line 596, in on_failure
    error('Task handler raised error: %r', exc,
[2023-04-24 18:53:11,530: WARNING/MainProcess] Message: 'Task handler raised error: %r'
Arguments: (ValueError('not enough values to unpack (expected 3, got 0)'),)
[2023-04-24 18:53:11,807: INFO/MainProcess] Task base.tasks.send_the_email[f8cfcd87-22cb-4cb6-bef4-5b3560b915fb] received
[2023-04-24 18:53:11,809: WARNING/MainProcess] --- Logging error ---
[2023-04-24 18:53:11,810: WARNING/MainProcess] Traceback (most recent call last):
[2023-04-24 18:53:11,810: WARNING/MainProcess]   File "C:\Users\User\AppData\Local\Programs\Python\Python311\Lib\logging\__init__.py", line 1110, in emit
    msg = self.format(record)
          ^^^^^^^^^^^^^^^^^^^
[2023-04-24 18:53:11,810: WARNING/MainProcess]   File "C:\Users\User\AppData\Local\Programs\Python\Python311\Lib\logging\__init__.py", line 953, in format
    return fmt.format(record)
           ^^^^^^^^^^^^^^^^^^
[2023-04-24 18:53:11,811: WARNING/MainProcess]   File "C:\Users\User\AppData\Local\Programs\Python\Python311\Lib\site-packages\celery\utils\log.py", line 146, in format
    msg = super().format(record)
          ^^^^^^^^^^^^^^^^^^^^^^
[2023-04-24 18:53:11,811: WARNING/MainProcess]   File "C:\Users\User\AppData\Local\Programs\Python\Python311\Lib\logging\__init__.py", line 695, in format
    record.exc_text = self.formatException(record.exc_info)
                      ^^^^^^^^^^^^^^^^^^^^^^^^^^^^^^^^^^^^^
[2023-04-24 18:53:11,811: WARNING/MainProcess]   File "C:\Users\User\AppData\Local\Programs\Python\Python311\Lib\site-packages\celery\utils\log.py", line 142, in formatException
    r = super().formatException(ei)
        ^^^^^^^^^^^^^^^^^^^^^^^^^^^
[2023-04-24 18:53:11,811: WARNING/MainProcess]   File "C:\Users\User\AppData\Local\Programs\Python\Python311\Lib\logging\__init__.py", line 645, in formatException
    traceback.print_exception(ei[0], ei[1], tb, None, sio)
[2023-04-24 18:53:11,811: WARNING/MainProcess]   File "C:\Users\User\AppData\Local\Programs\Python\Python311\Lib\traceback.py", line 124, in print_exception
    te = TracebackException(type(value), value, tb, limit=limit, compact=True)
         ^^^^^^^^^^^^^^^^^^^^^^^^^^^^^^^^^^^^^^^^^^^^^^^^^^^^^^^^^^^^^^^^^^^^^
[2023-04-24 18:53:11,811: WARNING/MainProcess]   File "C:\Users\User\AppData\Local\Programs\Python\Python311\Lib\traceback.py", line 690, in __init__
    self.stack = StackSummary._extract_from_extended_frame_gen(
                 ^^^^^^^^^^^^^^^^^^^^^^^^^^^^^^^^^^^^^^^^^^^^^^
[2023-04-24 18:53:11,811: WARNING/MainProcess]   File "C:\Users\User\AppData\Local\Programs\Python\Python311\Lib\traceback.py", line 416, in _extract_from_extended_frame_gen
    for f, (lineno, end_lineno, colno, end_colno) in frame_gen:
[2023-04-24 18:53:11,811: WARNING/MainProcess]   File "C:\Users\User\AppData\Local\Programs\Python\Python311\Lib\traceback.py", line 353, in _walk_tb_with_full_positions
    positions = _get_code_position(tb.tb_frame.f_code, tb.tb_lasti)
                ^^^^^^^^^^^^^^^^^^^^^^^^^^^^^^^^^^^^^^^^^^^^^^^^^^^
[2023-04-24 18:53:11,812: WARNING/MainProcess]   File "C:\Users\User\AppData\Local\Programs\Python\Python311\Lib\traceback.py", line 366, in _get_code_position
    positions_gen = code.co_positions()
                    ^^^^^^^^^^^^^^^^^
[2023-04-24 18:53:11,812: WARNING/MainProcess] AttributeError: '_Code' object has no attribute 'co_positions'
[2023-04-24 18:53:11,812: WARNING/MainProcess] Call stack:
[2023-04-24 18:53:11,812: WARNING/MainProcess]   File "C:\Users\User\AppData\Local\Programs\Python\Python311\Lib\threading.py", line 995, in _bootstrap
    self._bootstrap_inner()
[2023-04-24 18:53:11,812: WARNING/MainProcess]   File "C:\Users\User\AppData\Local\Programs\Python\Python311\Lib\threading.py", line 1038, in _bootstrap_inner
    self.run()
[2023-04-24 18:53:11,812: WARNING/MainProcess]   File "C:\Users\User\AppData\Local\Programs\Python\Python311\Lib\site-packages\billiard\pool.py", line 504, in run
    return self.body()
[2023-04-24 18:53:11,813: WARNING/MainProcess]   File "C:\Users\User\AppData\Local\Programs\Python\Python311\Lib\site-packages\billiard\pool.py", line 899, in body
    for _ in self._process_result(1.0):  # blocking
[2023-04-24 18:53:11,813: WARNING/MainProcess]   File "C:\Users\User\AppData\Local\Programs\Python\Python311\Lib\site-packages\billiard\pool.py", line 878, in _process_result
    on_state_change(task)
[2023-04-24 18:53:11,813: WARNING/MainProcess]   File "C:\Users\User\AppData\Local\Programs\Python\Python311\Lib\site-packages\billiard\pool.py", line 853, in on_state_change
    state_handlers[state](*args)
[2023-04-24 18:53:11,813: WARNING/MainProcess]   File "C:\Users\User\AppData\Local\Programs\Python\Python311\Lib\site-packages\billiard\pool.py", line 835, in on_ready
    item._set(i, obj)
[2023-04-24 18:53:11,813: WARNING/MainProcess]   File "C:\Users\User\AppData\Local\Programs\Python\Python311\Lib\site-packages\billiard\pool.py", line 1828, in _set
    self.safe_apply_callback(
[2023-04-24 18:53:11,813: WARNING/MainProcess]   File "C:\Users\User\AppData\Local\Programs\Python\Python311\Lib\site-packages\billiard\pool.py", line 1796, in safe_apply_callback
    fun(*args, **kwargs)
[2023-04-24 18:53:11,814: WARNING/MainProcess]   File "C:\Users\User\AppData\Local\Programs\Python\Python311\Lib\site-packages\celery\worker\request.py", line 596, in on_failure
    error('Task handler raised error: %r', exc,
[2023-04-24 18:53:11,814: WARNING/MainProcess] Message: 'Task handler raised error: %r'
Arguments: (ValueError('not enough values to unpack (expected 3, got 0)'),)
[2023-04-24 18:53:55,502: INFO/MainProcess] Task base.tasks.send_the_email[506a712c-6079-43f6-ab28-44cdd25ef9d4] received
[2023-04-24 18:53:55,517: WARNING/MainProcess] --- Logging error ---
[2023-04-24 18:53:55,517: WARNING/MainProcess] Traceback (most recent call last):
[2023-04-24 18:53:55,517: WARNING/MainProcess]   File "C:\Users\User\AppData\Local\Programs\Python\Python311\Lib\logging\__init__.py", line 1110, in emit
    msg = self.format(record)
          ^^^^^^^^^^^^^^^^^^^
[2023-04-24 18:53:55,517: WARNING/MainProcess]   File "C:\Users\User\AppData\Local\Programs\Python\Python311\Lib\logging\__init__.py", line 953, in format
    return fmt.format(record)
           ^^^^^^^^^^^^^^^^^^
[2023-04-24 18:53:55,517: WARNING/MainProcess]   File "C:\Users\User\AppData\Local\Programs\Python\Python311\Lib\site-packages\celery\utils\log.py", line 146, in format
    msg = super().format(record)
          ^^^^^^^^^^^^^^^^^^^^^^
[2023-04-24 18:53:55,517: WARNING/MainProcess]   File "C:\Users\User\AppData\Local\Programs\Python\Python311\Lib\logging\__init__.py", line 695, in format
    record.exc_text = self.formatException(record.exc_info)
                      ^^^^^^^^^^^^^^^^^^^^^^^^^^^^^^^^^^^^^
[2023-04-24 18:53:55,517: WARNING/MainProcess]   File "C:\Users\User\AppData\Local\Programs\Python\Python311\Lib\site-packages\celery\utils\log.py", line 142, in formatException
    r = super().formatException(ei)
        ^^^^^^^^^^^^^^^^^^^^^^^^^^^
[2023-04-24 18:53:55,517: WARNING/MainProcess]   File "C:\Users\User\AppData\Local\Programs\Python\Python311\Lib\logging\__init__.py", line 645, in formatException
    traceback.print_exception(ei[0], ei[1], tb, None, sio)
[2023-04-24 18:53:55,517: WARNING/MainProcess]   File "C:\Users\User\AppData\Local\Programs\Python\Python311\Lib\traceback.py", line 124, in print_exception
    te = TracebackException(type(value), value, tb, limit=limit, compact=True)
         ^^^^^^^^^^^^^^^^^^^^^^^^^^^^^^^^^^^^^^^^^^^^^^^^^^^^^^^^^^^^^^^^^^^^^
[2023-04-24 18:53:55,517: WARNING/MainProcess]   File "C:\Users\User\AppData\Local\Programs\Python\Python311\Lib\traceback.py", line 690, in __init__
    self.stack = StackSummary._extract_from_extended_frame_gen(
                 ^^^^^^^^^^^^^^^^^^^^^^^^^^^^^^^^^^^^^^^^^^^^^^
[2023-04-24 18:53:55,517: WARNING/MainProcess]   File "C:\Users\User\AppData\Local\Programs\Python\Python311\Lib\traceback.py", line 416, in _extract_from_extended_frame_gen
    for f, (lineno, end_lineno, colno, end_colno) in frame_gen:
[2023-04-24 18:53:55,517: WARNING/MainProcess]   File "C:\Users\User\AppData\Local\Programs\Python\Python311\Lib\traceback.py", line 353, in _walk_tb_with_full_positions
    positions = _get_code_position(tb.tb_frame.f_code, tb.tb_lasti)
                ^^^^^^^^^^^^^^^^^^^^^^^^^^^^^^^^^^^^^^^^^^^^^^^^^^^
[2023-04-24 18:53:55,517: WARNING/MainProcess]   File "C:\Users\User\AppData\Local\Programs\Python\Python311\Lib\traceback.py", line 366, in _get_code_position
    positions_gen = code.co_positions()
                    ^^^^^^^^^^^^^^^^^
[2023-04-24 18:53:55,517: WARNING/MainProcess] AttributeError: '_Code' object has no attribute 'co_positions'
[2023-04-24 18:53:55,517: WARNING/MainProcess] Call stack:
[2023-04-24 18:53:55,517: WARNING/MainProcess]   File "C:\Users\User\AppData\Local\Programs\Python\Python311\Lib\threading.py", line 995, in _bootstrap
    self._bootstrap_inner()
[2023-04-24 18:53:55,517: WARNING/MainProcess]   File "C:\Users\User\AppData\Local\Programs\Python\Python311\Lib\threading.py", line 1038, in _bootstrap_inner
    self.run()
[2023-04-24 18:53:55,517: WARNING/MainProcess]   File "C:\Users\User\AppData\Local\Programs\Python\Python311\Lib\site-packages\billiard\pool.py", line 504, in run
    return self.body()
[2023-04-24 18:53:55,517: WARNING/MainProcess]   File "C:\Users\User\AppData\Local\Programs\Python\Python311\Lib\site-packages\billiard\pool.py", line 899, in body
    for _ in self._process_result(1.0):  # blocking
[2023-04-24 18:53:55,517: WARNING/MainProcess]   File "C:\Users\User\AppData\Local\Programs\Python\Python311\Lib\site-packages\billiard\pool.py", line 878, in _process_result
    on_state_change(task)
[2023-04-24 18:53:55,517: WARNING/MainProcess]   File "C:\Users\User\AppData\Local\Programs\Python\Python311\Lib\site-packages\billiard\pool.py", line 853, in on_state_change
    state_handlers[state](*args)
[2023-04-24 18:53:55,517: WARNING/MainProcess]   File "C:\Users\User\AppData\Local\Programs\Python\Python311\Lib\site-packages\billiard\pool.py", line 835, in on_ready
    item._set(i, obj)
[2023-04-24 18:53:55,517: WARNING/MainProcess]   File "C:\Users\User\AppData\Local\Programs\Python\Python311\Lib\site-packages\billiard\pool.py", line 1828, in _set
    self.safe_apply_callback(
[2023-04-24 18:53:55,517: WARNING/MainProcess]   File "C:\Users\User\AppData\Local\Programs\Python\Python311\Lib\site-packages\billiard\pool.py", line 1796, in safe_apply_callback
    fun(*args, **kwargs)
[2023-04-24 18:53:55,517: WARNING/MainProcess]   File "C:\Users\User\AppData\Local\Programs\Python\Python311\Lib\site-packages\celery\worker\request.py", line 596, in on_failure
    error('Task handler raised error: %r', exc,
[2023-04-24 18:53:55,517: WARNING/MainProcess] Message: 'Task handler raised error: %r'
Arguments: (ValueError('not enough values to unpack (expected 3, got 0)'),)
[2023-04-24 18:55:17,324: INFO/MainProcess] Task base.tasks.send_the_email[24cbb212-7ec2-45d5-87c9-229a8ef01540] received
[2023-04-24 18:55:17,324: WARNING/MainProcess] --- Logging error ---
[2023-04-24 18:55:17,324: WARNING/MainProcess] Traceback (most recent call last):
[2023-04-24 18:55:17,324: WARNING/MainProcess]   File "C:\Users\User\AppData\Local\Programs\Python\Python311\Lib\logging\__init__.py", line 1110, in emit
    msg = self.format(record)
          ^^^^^^^^^^^^^^^^^^^
[2023-04-24 18:55:17,324: WARNING/MainProcess]   File "C:\Users\User\AppData\Local\Programs\Python\Python311\Lib\logging\__init__.py", line 953, in format
    return fmt.format(record)
           ^^^^^^^^^^^^^^^^^^
[2023-04-24 18:55:17,324: WARNING/MainProcess]   File "C:\Users\User\AppData\Local\Programs\Python\Python311\Lib\site-packages\celery\utils\log.py", line 146, in format
    msg = super().format(record)
          ^^^^^^^^^^^^^^^^^^^^^^
[2023-04-24 18:55:17,324: WARNING/MainProcess]   File "C:\Users\User\AppData\Local\Programs\Python\Python311\Lib\logging\__init__.py", line 695, in format
    record.exc_text = self.formatException(record.exc_info)
                      ^^^^^^^^^^^^^^^^^^^^^^^^^^^^^^^^^^^^^
[2023-04-24 18:55:17,324: WARNING/MainProcess]   File "C:\Users\User\AppData\Local\Programs\Python\Python311\Lib\site-packages\celery\utils\log.py", line 142, in formatException
    r = super().formatException(ei)
        ^^^^^^^^^^^^^^^^^^^^^^^^^^^
[2023-04-24 18:55:17,324: WARNING/MainProcess]   File "C:\Users\User\AppData\Local\Programs\Python\Python311\Lib\logging\__init__.py", line 645, in formatException
    traceback.print_exception(ei[0], ei[1], tb, None, sio)
[2023-04-24 18:55:17,324: WARNING/MainProcess]   File "C:\Users\User\AppData\Local\Programs\Python\Python311\Lib\traceback.py", line 124, in print_exception
    te = TracebackException(type(value), value, tb, limit=limit, compact=True)
         ^^^^^^^^^^^^^^^^^^^^^^^^^^^^^^^^^^^^^^^^^^^^^^^^^^^^^^^^^^^^^^^^^^^^^
[2023-04-24 18:55:17,324: WARNING/MainProcess]   File "C:\Users\User\AppData\Local\Programs\Python\Python311\Lib\traceback.py", line 690, in __init__
    self.stack = StackSummary._extract_from_extended_frame_gen(
                 ^^^^^^^^^^^^^^^^^^^^^^^^^^^^^^^^^^^^^^^^^^^^^^
[2023-04-24 18:55:17,324: WARNING/MainProcess]   File "C:\Users\User\AppData\Local\Programs\Python\Python311\Lib\traceback.py", line 416, in _extract_from_extended_frame_gen
    for f, (lineno, end_lineno, colno, end_colno) in frame_gen:
[2023-04-24 18:55:17,324: WARNING/MainProcess]   File "C:\Users\User\AppData\Local\Programs\Python\Python311\Lib\traceback.py", line 353, in _walk_tb_with_full_positions
    positions = _get_code_position(tb.tb_frame.f_code, tb.tb_lasti)
                ^^^^^^^^^^^^^^^^^^^^^^^^^^^^^^^^^^^^^^^^^^^^^^^^^^^
[2023-04-24 18:55:17,324: WARNING/MainProcess]   File "C:\Users\User\AppData\Local\Programs\Python\Python311\Lib\traceback.py", line 366, in _get_code_position
    positions_gen = code.co_positions()
                    ^^^^^^^^^^^^^^^^^
[2023-04-24 18:55:17,324: WARNING/MainProcess] AttributeError: '_Code' object has no attribute 'co_positions'
[2023-04-24 18:55:17,324: WARNING/MainProcess] Call stack:
[2023-04-24 18:55:17,324: WARNING/MainProcess]   File "C:\Users\User\AppData\Local\Programs\Python\Python311\Lib\threading.py", line 995, in _bootstrap
    self._bootstrap_inner()
[2023-04-24 18:55:17,324: WARNING/MainProcess]   File "C:\Users\User\AppData\Local\Programs\Python\Python311\Lib\threading.py", line 1038, in _bootstrap_inner
    self.run()
[2023-04-24 18:55:17,324: WARNING/MainProcess]   File "C:\Users\User\AppData\Local\Programs\Python\Python311\Lib\site-packages\billiard\pool.py", line 504, in run
    return self.body()
[2023-04-24 18:55:17,324: WARNING/MainProcess]   File "C:\Users\User\AppData\Local\Programs\Python\Python311\Lib\site-packages\billiard\pool.py", line 899, in body
    for _ in self._process_result(1.0):  # blocking
[2023-04-24 18:55:17,324: WARNING/MainProcess]   File "C:\Users\User\AppData\Local\Programs\Python\Python311\Lib\site-packages\billiard\pool.py", line 878, in _process_result
    on_state_change(task)
[2023-04-24 18:55:17,324: WARNING/MainProcess]   File "C:\Users\User\AppData\Local\Programs\Python\Python311\Lib\site-packages\billiard\pool.py", line 853, in on_state_change
    state_handlers[state](*args)
[2023-04-24 18:55:17,324: WARNING/MainProcess]   File "C:\Users\User\AppData\Local\Programs\Python\Python311\Lib\site-packages\billiard\pool.py", line 835, in on_ready
    item._set(i, obj)
[2023-04-24 18:55:17,324: WARNING/MainProcess]   File "C:\Users\User\AppData\Local\Programs\Python\Python311\Lib\site-packages\billiard\pool.py", line 1828, in _set
    self.safe_apply_callback(
[2023-04-24 18:55:17,324: WARNING/MainProcess]   File "C:\Users\User\AppData\Local\Programs\Python\Python311\Lib\site-packages\billiard\pool.py", line 1796, in safe_apply_callback
    fun(*args, **kwargs)
[2023-04-24 18:55:17,324: WARNING/MainProcess]   File "C:\Users\User\AppData\Local\Programs\Python\Python311\Lib\site-packages\celery\worker\request.py", line 596, in on_failure
    error('Task handler raised error: %r', exc,
[2023-04-24 18:55:17,324: WARNING/MainProcess] Message: 'Task handler raised error: %r'
Arguments: (ValueError('not enough values to unpack (expected 3, got 0)'),)
[2023-04-24 18:55:17,538: INFO/MainProcess] Task base.tasks.send_the_email[0f7de765-37c7-4089-8f68-5bffef709a4c] received
[2023-04-24 18:55:17,538: WARNING/MainProcess] --- Logging error ---
[2023-04-24 18:55:17,538: WARNING/MainProcess] Traceback (most recent call last):
[2023-04-24 18:55:17,538: WARNING/MainProcess]   File "C:\Users\User\AppData\Local\Programs\Python\Python311\Lib\logging\__init__.py", line 1110, in emit
    msg = self.format(record)
          ^^^^^^^^^^^^^^^^^^^
[2023-04-24 18:55:17,554: WARNING/MainProcess]   File "C:\Users\User\AppData\Local\Programs\Python\Python311\Lib\logging\__init__.py", line 953, in format
    return fmt.format(record)
           ^^^^^^^^^^^^^^^^^^
[2023-04-24 18:55:17,554: WARNING/MainProcess]   File "C:\Users\User\AppData\Local\Programs\Python\Python311\Lib\site-packages\celery\utils\log.py", line 146, in format
    msg = super().format(record)
          ^^^^^^^^^^^^^^^^^^^^^^
[2023-04-24 18:55:17,554: WARNING/MainProcess]   File "C:\Users\User\AppData\Local\Programs\Python\Python311\Lib\logging\__init__.py", line 695, in format
    record.exc_text = self.formatException(record.exc_info)
                      ^^^^^^^^^^^^^^^^^^^^^^^^^^^^^^^^^^^^^
[2023-04-24 18:55:17,554: WARNING/MainProcess]   File "C:\Users\User\AppData\Local\Programs\Python\Python311\Lib\site-packages\celery\utils\log.py", line 142, in formatException
    r = super().formatException(ei)
        ^^^^^^^^^^^^^^^^^^^^^^^^^^^
[2023-04-24 18:55:17,554: WARNING/MainProcess]   File "C:\Users\User\AppData\Local\Programs\Python\Python311\Lib\logging\__init__.py", line 645, in formatException
    traceback.print_exception(ei[0], ei[1], tb, None, sio)
[2023-04-24 18:55:17,554: WARNING/MainProcess]   File "C:\Users\User\AppData\Local\Programs\Python\Python311\Lib\traceback.py", line 124, in print_exception
    te = TracebackException(type(value), value, tb, limit=limit, compact=True)
         ^^^^^^^^^^^^^^^^^^^^^^^^^^^^^^^^^^^^^^^^^^^^^^^^^^^^^^^^^^^^^^^^^^^^^
[2023-04-24 18:55:17,554: WARNING/MainProcess]   File "C:\Users\User\AppData\Local\Programs\Python\Python311\Lib\traceback.py", line 690, in __init__
    self.stack = StackSummary._extract_from_extended_frame_gen(
                 ^^^^^^^^^^^^^^^^^^^^^^^^^^^^^^^^^^^^^^^^^^^^^^
[2023-04-24 18:55:17,554: WARNING/MainProcess]   File "C:\Users\User\AppData\Local\Programs\Python\Python311\Lib\traceback.py", line 416, in _extract_from_extended_frame_gen
    for f, (lineno, end_lineno, colno, end_colno) in frame_gen:
[2023-04-24 18:55:17,554: WARNING/MainProcess]   File "C:\Users\User\AppData\Local\Programs\Python\Python311\Lib\traceback.py", line 353, in _walk_tb_with_full_positions
    positions = _get_code_position(tb.tb_frame.f_code, tb.tb_lasti)
                ^^^^^^^^^^^^^^^^^^^^^^^^^^^^^^^^^^^^^^^^^^^^^^^^^^^
[2023-04-24 18:55:17,554: WARNING/MainProcess]   File "C:\Users\User\AppData\Local\Programs\Python\Python311\Lib\traceback.py", line 366, in _get_code_position
    positions_gen = code.co_positions()
                    ^^^^^^^^^^^^^^^^^
[2023-04-24 18:55:17,554: WARNING/MainProcess] AttributeError: '_Code' object has no attribute 'co_positions'
[2023-04-24 18:55:17,554: WARNING/MainProcess] Call stack:
[2023-04-24 18:55:17,554: WARNING/MainProcess]   File "C:\Users\User\AppData\Local\Programs\Python\Python311\Lib\threading.py", line 995, in _bootstrap
    self._bootstrap_inner()
[2023-04-24 18:55:17,554: WARNING/MainProcess]   File "C:\Users\User\AppData\Local\Programs\Python\Python311\Lib\threading.py", line 1038, in _bootstrap_inner
    self.run()
[2023-04-24 18:55:17,554: WARNING/MainProcess]   File "C:\Users\User\AppData\Local\Programs\Python\Python311\Lib\site-packages\billiard\pool.py", line 504, in run
    return self.body()
[2023-04-24 18:55:17,554: WARNING/MainProcess]   File "C:\Users\User\AppData\Local\Programs\Python\Python311\Lib\site-packages\billiard\pool.py", line 899, in body
    for _ in self._process_result(1.0):  # blocking
[2023-04-24 18:55:17,554: WARNING/MainProcess]   File "C:\Users\User\AppData\Local\Programs\Python\Python311\Lib\site-packages\billiard\pool.py", line 878, in _process_result
    on_state_change(task)
[2023-04-24 18:55:17,554: WARNING/MainProcess]   File "C:\Users\User\AppData\Local\Programs\Python\Python311\Lib\site-packages\billiard\pool.py", line 853, in on_state_change
    state_handlers[state](*args)
[2023-04-24 18:55:17,554: WARNING/MainProcess]   File "C:\Users\User\AppData\Local\Programs\Python\Python311\Lib\site-packages\billiard\pool.py", line 835, in on_ready
    item._set(i, obj)
[2023-04-24 18:55:17,554: WARNING/MainProcess]   File "C:\Users\User\AppData\Local\Programs\Python\Python311\Lib\site-packages\billiard\pool.py", line 1828, in _set
    self.safe_apply_callback(
[2023-04-24 18:55:17,554: WARNING/MainProcess]   File "C:\Users\User\AppData\Local\Programs\Python\Python311\Lib\site-packages\billiard\pool.py", line 1796, in safe_apply_callback
    fun(*args, **kwargs)
[2023-04-24 18:55:17,554: WARNING/MainProcess]   File "C:\Users\User\AppData\Local\Programs\Python\Python311\Lib\site-packages\celery\worker\request.py", line 596, in on_failure
    error('Task handler raised error: %r', exc,
[2023-04-24 18:55:17,554: WARNING/MainProcess] Message: 'Task handler raised error: %r'
Arguments: (ValueError('not enough values to unpack (expected 3, got 0)'),)
[2023-04-24 18:55:17,825: INFO/MainProcess] Task base.tasks.send_the_email[d87ef52f-383b-4d81-b227-0e870486c87e] received
[2023-04-24 18:55:17,825: WARNING/MainProcess] --- Logging error ---
[2023-04-24 18:55:17,825: WARNING/MainProcess] Traceback (most recent call last):
[2023-04-24 18:55:17,825: WARNING/MainProcess]   File "C:\Users\User\AppData\Local\Programs\Python\Python311\Lib\logging\__init__.py", line 1110, in emit
    msg = self.format(record)
          ^^^^^^^^^^^^^^^^^^^
[2023-04-24 18:55:17,840: WARNING/MainProcess]   File "C:\Users\User\AppData\Local\Programs\Python\Python311\Lib\logging\__init__.py", line 953, in format
    return fmt.format(record)
           ^^^^^^^^^^^^^^^^^^
[2023-04-24 18:55:17,840: WARNING/MainProcess]   File "C:\Users\User\AppData\Local\Programs\Python\Python311\Lib\site-packages\celery\utils\log.py", line 146, in format
    msg = super().format(record)
          ^^^^^^^^^^^^^^^^^^^^^^
[2023-04-24 18:55:17,840: WARNING/MainProcess]   File "C:\Users\User\AppData\Local\Programs\Python\Python311\Lib\logging\__init__.py", line 695, in format
    record.exc_text = self.formatException(record.exc_info)
                      ^^^^^^^^^^^^^^^^^^^^^^^^^^^^^^^^^^^^^
[2023-04-24 18:55:17,840: WARNING/MainProcess]   File "C:\Users\User\AppData\Local\Programs\Python\Python311\Lib\site-packages\celery\utils\log.py", line 142, in formatException
    r = super().formatException(ei)
        ^^^^^^^^^^^^^^^^^^^^^^^^^^^
[2023-04-24 18:55:17,840: WARNING/MainProcess]   File "C:\Users\User\AppData\Local\Programs\Python\Python311\Lib\logging\__init__.py", line 645, in formatException
    traceback.print_exception(ei[0], ei[1], tb, None, sio)
[2023-04-24 18:55:17,840: WARNING/MainProcess]   File "C:\Users\User\AppData\Local\Programs\Python\Python311\Lib\traceback.py", line 124, in print_exception
    te = TracebackException(type(value), value, tb, limit=limit, compact=True)
         ^^^^^^^^^^^^^^^^^^^^^^^^^^^^^^^^^^^^^^^^^^^^^^^^^^^^^^^^^^^^^^^^^^^^^
[2023-04-24 18:55:17,840: WARNING/MainProcess]   File "C:\Users\User\AppData\Local\Programs\Python\Python311\Lib\traceback.py", line 690, in __init__
    self.stack = StackSummary._extract_from_extended_frame_gen(
                 ^^^^^^^^^^^^^^^^^^^^^^^^^^^^^^^^^^^^^^^^^^^^^^
[2023-04-24 18:55:17,840: WARNING/MainProcess]   File "C:\Users\User\AppData\Local\Programs\Python\Python311\Lib\traceback.py", line 416, in _extract_from_extended_frame_gen
    for f, (lineno, end_lineno, colno, end_colno) in frame_gen:
[2023-04-24 18:55:17,840: WARNING/MainProcess]   File "C:\Users\User\AppData\Local\Programs\Python\Python311\Lib\traceback.py", line 353, in _walk_tb_with_full_positions
    positions = _get_code_position(tb.tb_frame.f_code, tb.tb_lasti)
                ^^^^^^^^^^^^^^^^^^^^^^^^^^^^^^^^^^^^^^^^^^^^^^^^^^^
[2023-04-24 18:55:17,840: WARNING/MainProcess]   File "C:\Users\User\AppData\Local\Programs\Python\Python311\Lib\traceback.py", line 366, in _get_code_position
    positions_gen = code.co_positions()
                    ^^^^^^^^^^^^^^^^^
[2023-04-24 18:55:17,840: WARNING/MainProcess] AttributeError: '_Code' object has no attribute 'co_positions'
[2023-04-24 18:55:17,840: WARNING/MainProcess] Call stack:
[2023-04-24 18:55:17,840: WARNING/MainProcess]   File "C:\Users\User\AppData\Local\Programs\Python\Python311\Lib\threading.py", line 995, in _bootstrap
    self._bootstrap_inner()
[2023-04-24 18:55:17,840: WARNING/MainProcess]   File "C:\Users\User\AppData\Local\Programs\Python\Python311\Lib\threading.py", line 1038, in _bootstrap_inner
    self.run()
[2023-04-24 18:55:17,840: WARNING/MainProcess]   File "C:\Users\User\AppData\Local\Programs\Python\Python311\Lib\site-packages\billiard\pool.py", line 504, in run
    return self.body()
[2023-04-24 18:55:17,840: WARNING/MainProcess]   File "C:\Users\User\AppData\Local\Programs\Python\Python311\Lib\site-packages\billiard\pool.py", line 899, in body
    for _ in self._process_result(1.0):  # blocking
[2023-04-24 18:55:17,840: WARNING/MainProcess]   File "C:\Users\User\AppData\Local\Programs\Python\Python311\Lib\site-packages\billiard\pool.py", line 878, in _process_result
    on_state_change(task)
[2023-04-24 18:55:17,840: WARNING/MainProcess]   File "C:\Users\User\AppData\Local\Programs\Python\Python311\Lib\site-packages\billiard\pool.py", line 853, in on_state_change
    state_handlers[state](*args)
[2023-04-24 18:55:17,840: WARNING/MainProcess]   File "C:\Users\User\AppData\Local\Programs\Python\Python311\Lib\site-packages\billiard\pool.py", line 835, in on_ready
    item._set(i, obj)
[2023-04-24 18:55:17,840: WARNING/MainProcess]   File "C:\Users\User\AppData\Local\Programs\Python\Python311\Lib\site-packages\billiard\pool.py", line 1828, in _set
    self.safe_apply_callback(
[2023-04-24 18:55:17,840: WARNING/MainProcess]   File "C:\Users\User\AppData\Local\Programs\Python\Python311\Lib\site-packages\billiard\pool.py", line 1796, in safe_apply_callback
    fun(*args, **kwargs)
[2023-04-24 18:55:17,840: WARNING/MainProcess]   File "C:\Users\User\AppData\Local\Programs\Python\Python311\Lib\site-packages\celery\worker\request.py", line 596, in on_failure
    error('Task handler raised error: %r', exc,
[2023-04-24 18:55:17,840: WARNING/MainProcess] Message: 'Task handler raised error: %r'
Arguments: (ValueError('not enough values to unpack (expected 3, got 0)'),)
[2023-04-24 18:55:18,028: INFO/MainProcess] Task base.tasks.send_the_email[6e66521d-5ad0-44ff-b606-6a73acae5fb1] received
[2023-04-24 18:55:18,028: WARNING/MainProcess] --- Logging error ---
[2023-04-24 18:55:18,028: WARNING/MainProcess] Traceback (most recent call last):
[2023-04-24 18:55:18,028: WARNING/MainProcess]   File "C:\Users\User\AppData\Local\Programs\Python\Python311\Lib\logging\__init__.py", line 1110, in emit
    msg = self.format(record)
          ^^^^^^^^^^^^^^^^^^^
[2023-04-24 18:55:18,028: WARNING/MainProcess]   File "C:\Users\User\AppData\Local\Programs\Python\Python311\Lib\logging\__init__.py", line 953, in format
    return fmt.format(record)
           ^^^^^^^^^^^^^^^^^^
[2023-04-24 18:55:18,028: WARNING/MainProcess]   File "C:\Users\User\AppData\Local\Programs\Python\Python311\Lib\site-packages\celery\utils\log.py", line 146, in format
    msg = super().format(record)
          ^^^^^^^^^^^^^^^^^^^^^^
[2023-04-24 18:55:18,043: WARNING/MainProcess]   File "C:\Users\User\AppData\Local\Programs\Python\Python311\Lib\logging\__init__.py", line 695, in format
    record.exc_text = self.formatException(record.exc_info)
                      ^^^^^^^^^^^^^^^^^^^^^^^^^^^^^^^^^^^^^
[2023-04-24 18:55:18,043: WARNING/MainProcess]   File "C:\Users\User\AppData\Local\Programs\Python\Python311\Lib\site-packages\celery\utils\log.py", line 142, in formatException
    r = super().formatException(ei)
        ^^^^^^^^^^^^^^^^^^^^^^^^^^^
[2023-04-24 18:55:18,043: WARNING/MainProcess]   File "C:\Users\User\AppData\Local\Programs\Python\Python311\Lib\logging\__init__.py", line 645, in formatException
    traceback.print_exception(ei[0], ei[1], tb, None, sio)
[2023-04-24 18:55:18,043: WARNING/MainProcess]   File "C:\Users\User\AppData\Local\Programs\Python\Python311\Lib\traceback.py", line 124, in print_exception
    te = TracebackException(type(value), value, tb, limit=limit, compact=True)
         ^^^^^^^^^^^^^^^^^^^^^^^^^^^^^^^^^^^^^^^^^^^^^^^^^^^^^^^^^^^^^^^^^^^^^
[2023-04-24 18:55:18,043: WARNING/MainProcess]   File "C:\Users\User\AppData\Local\Programs\Python\Python311\Lib\traceback.py", line 690, in __init__
    self.stack = StackSummary._extract_from_extended_frame_gen(
                 ^^^^^^^^^^^^^^^^^^^^^^^^^^^^^^^^^^^^^^^^^^^^^^
[2023-04-24 18:55:18,043: WARNING/MainProcess]   File "C:\Users\User\AppData\Local\Programs\Python\Python311\Lib\traceback.py", line 416, in _extract_from_extended_frame_gen
    for f, (lineno, end_lineno, colno, end_colno) in frame_gen:
[2023-04-24 18:55:18,043: WARNING/MainProcess]   File "C:\Users\User\AppData\Local\Programs\Python\Python311\Lib\traceback.py", line 353, in _walk_tb_with_full_positions
    positions = _get_code_position(tb.tb_frame.f_code, tb.tb_lasti)
                ^^^^^^^^^^^^^^^^^^^^^^^^^^^^^^^^^^^^^^^^^^^^^^^^^^^
[2023-04-24 18:55:18,043: WARNING/MainProcess]   File "C:\Users\User\AppData\Local\Programs\Python\Python311\Lib\traceback.py", line 366, in _get_code_position
    positions_gen = code.co_positions()
                    ^^^^^^^^^^^^^^^^^
[2023-04-24 18:55:18,043: WARNING/MainProcess] AttributeError: '_Code' object has no attribute 'co_positions'
[2023-04-24 18:55:18,043: WARNING/MainProcess] Call stack:
[2023-04-24 18:55:18,043: WARNING/MainProcess]   File "C:\Users\User\AppData\Local\Programs\Python\Python311\Lib\threading.py", line 995, in _bootstrap
    self._bootstrap_inner()
[2023-04-24 18:55:18,043: WARNING/MainProcess]   File "C:\Users\User\AppData\Local\Programs\Python\Python311\Lib\threading.py", line 1038, in _bootstrap_inner
    self.run()
[2023-04-24 18:55:18,043: WARNING/MainProcess]   File "C:\Users\User\AppData\Local\Programs\Python\Python311\Lib\site-packages\billiard\pool.py", line 504, in run
    return self.body()
[2023-04-24 18:55:18,043: WARNING/MainProcess]   File "C:\Users\User\AppData\Local\Programs\Python\Python311\Lib\site-packages\billiard\pool.py", line 899, in body
    for _ in self._process_result(1.0):  # blocking
[2023-04-24 18:55:18,043: WARNING/MainProcess]   File "C:\Users\User\AppData\Local\Programs\Python\Python311\Lib\site-packages\billiard\pool.py", line 878, in _process_result
    on_state_change(task)
[2023-04-24 18:55:18,043: WARNING/MainProcess]   File "C:\Users\User\AppData\Local\Programs\Python\Python311\Lib\site-packages\billiard\pool.py", line 853, in on_state_change
    state_handlers[state](*args)
[2023-04-24 18:55:18,043: WARNING/MainProcess]   File "C:\Users\User\AppData\Local\Programs\Python\Python311\Lib\site-packages\billiard\pool.py", line 835, in on_ready
    item._set(i, obj)
[2023-04-24 18:55:18,043: WARNING/MainProcess]   File "C:\Users\User\AppData\Local\Programs\Python\Python311\Lib\site-packages\billiard\pool.py", line 1828, in _set
    self.safe_apply_callback(
[2023-04-24 18:55:18,043: WARNING/MainProcess]   File "C:\Users\User\AppData\Local\Programs\Python\Python311\Lib\site-packages\billiard\pool.py", line 1796, in safe_apply_callback
    fun(*args, **kwargs)
[2023-04-24 18:55:18,043: WARNING/MainProcess]   File "C:\Users\User\AppData\Local\Programs\Python\Python311\Lib\site-packages\celery\worker\request.py", line 596, in on_failure
    error('Task handler raised error: %r', exc,
[2023-04-24 18:55:18,043: WARNING/MainProcess] Message: 'Task handler raised error: %r'
Arguments: (ValueError('not enough values to unpack (expected 3, got 0)'),)
[2023-04-24 18:55:18,172: INFO/MainProcess] Task base.tasks.send_the_email[540b2f9f-7222-415c-b012-c9da57a2c27f] received
[2023-04-24 18:55:18,172: WARNING/MainProcess] --- Logging error ---
[2023-04-24 18:55:18,172: WARNING/MainProcess] Traceback (most recent call last):
[2023-04-24 18:55:18,172: WARNING/MainProcess]   File "C:\Users\User\AppData\Local\Programs\Python\Python311\Lib\logging\__init__.py", line 1110, in emit
    msg = self.format(record)
          ^^^^^^^^^^^^^^^^^^^
[2023-04-24 18:55:18,172: WARNING/MainProcess]   File "C:\Users\User\AppData\Local\Programs\Python\Python311\Lib\logging\__init__.py", line 953, in format
    return fmt.format(record)
           ^^^^^^^^^^^^^^^^^^
[2023-04-24 18:55:18,172: WARNING/MainProcess]   File "C:\Users\User\AppData\Local\Programs\Python\Python311\Lib\site-packages\celery\utils\log.py", line 146, in format
    msg = super().format(record)
          ^^^^^^^^^^^^^^^^^^^^^^
[2023-04-24 18:55:18,172: WARNING/MainProcess]   File "C:\Users\User\AppData\Local\Programs\Python\Python311\Lib\logging\__init__.py", line 695, in format
    record.exc_text = self.formatException(record.exc_info)
                      ^^^^^^^^^^^^^^^^^^^^^^^^^^^^^^^^^^^^^
[2023-04-24 18:55:18,172: WARNING/MainProcess]   File "C:\Users\User\AppData\Local\Programs\Python\Python311\Lib\site-packages\celery\utils\log.py", line 142, in formatException
    r = super().formatException(ei)
        ^^^^^^^^^^^^^^^^^^^^^^^^^^^
[2023-04-24 18:55:18,172: WARNING/MainProcess]   File "C:\Users\User\AppData\Local\Programs\Python\Python311\Lib\logging\__init__.py", line 645, in formatException
    traceback.print_exception(ei[0], ei[1], tb, None, sio)
[2023-04-24 18:55:18,172: WARNING/MainProcess]   File "C:\Users\User\AppData\Local\Programs\Python\Python311\Lib\traceback.py", line 124, in print_exception
    te = TracebackException(type(value), value, tb, limit=limit, compact=True)
         ^^^^^^^^^^^^^^^^^^^^^^^^^^^^^^^^^^^^^^^^^^^^^^^^^^^^^^^^^^^^^^^^^^^^^
[2023-04-24 18:55:18,172: WARNING/MainProcess]   File "C:\Users\User\AppData\Local\Programs\Python\Python311\Lib\traceback.py", line 690, in __init__
    self.stack = StackSummary._extract_from_extended_frame_gen(
                 ^^^^^^^^^^^^^^^^^^^^^^^^^^^^^^^^^^^^^^^^^^^^^^
[2023-04-24 18:55:18,172: WARNING/MainProcess]   File "C:\Users\User\AppData\Local\Programs\Python\Python311\Lib\traceback.py", line 416, in _extract_from_extended_frame_gen
    for f, (lineno, end_lineno, colno, end_colno) in frame_gen:
[2023-04-24 18:55:18,172: WARNING/MainProcess]   File "C:\Users\User\AppData\Local\Programs\Python\Python311\Lib\traceback.py", line 353, in _walk_tb_with_full_positions
    positions = _get_code_position(tb.tb_frame.f_code, tb.tb_lasti)
                ^^^^^^^^^^^^^^^^^^^^^^^^^^^^^^^^^^^^^^^^^^^^^^^^^^^
[2023-04-24 18:55:18,172: WARNING/MainProcess]   File "C:\Users\User\AppData\Local\Programs\Python\Python311\Lib\traceback.py", line 366, in _get_code_position
    positions_gen = code.co_positions()
                    ^^^^^^^^^^^^^^^^^
[2023-04-24 18:55:18,172: WARNING/MainProcess] AttributeError: '_Code' object has no attribute 'co_positions'
[2023-04-24 18:55:18,172: WARNING/MainProcess] Call stack:
[2023-04-24 18:55:18,172: WARNING/MainProcess]   File "C:\Users\User\AppData\Local\Programs\Python\Python311\Lib\threading.py", line 995, in _bootstrap
    self._bootstrap_inner()
[2023-04-24 18:55:18,172: WARNING/MainProcess]   File "C:\Users\User\AppData\Local\Programs\Python\Python311\Lib\threading.py", line 1038, in _bootstrap_inner
    self.run()
[2023-04-24 18:55:18,172: WARNING/MainProcess]   File "C:\Users\User\AppData\Local\Programs\Python\Python311\Lib\site-packages\billiard\pool.py", line 504, in run
    return self.body()
[2023-04-24 18:55:18,172: WARNING/MainProcess]   File "C:\Users\User\AppData\Local\Programs\Python\Python311\Lib\site-packages\billiard\pool.py", line 899, in body
    for _ in self._process_result(1.0):  # blocking
[2023-04-24 18:55:18,172: WARNING/MainProcess]   File "C:\Users\User\AppData\Local\Programs\Python\Python311\Lib\site-packages\billiard\pool.py", line 878, in _process_result
    on_state_change(task)
[2023-04-24 18:55:18,172: WARNING/MainProcess]   File "C:\Users\User\AppData\Local\Programs\Python\Python311\Lib\site-packages\billiard\pool.py", line 853, in on_state_change
    state_handlers[state](*args)
[2023-04-24 18:55:18,172: WARNING/MainProcess]   File "C:\Users\User\AppData\Local\Programs\Python\Python311\Lib\site-packages\billiard\pool.py", line 835, in on_ready
    item._set(i, obj)
[2023-04-24 18:55:18,172: WARNING/MainProcess]   File "C:\Users\User\AppData\Local\Programs\Python\Python311\Lib\site-packages\billiard\pool.py", line 1828, in _set
    self.safe_apply_callback(
[2023-04-24 18:55:18,172: WARNING/MainProcess]   File "C:\Users\User\AppData\Local\Programs\Python\Python311\Lib\site-packages\billiard\pool.py", line 1796, in safe_apply_callback
    fun(*args, **kwargs)
[2023-04-24 18:55:18,172: WARNING/MainProcess]   File "C:\Users\User\AppData\Local\Programs\Python\Python311\Lib\site-packages\celery\worker\request.py", line 596, in on_failure
    error('Task handler raised error: %r', exc,
[2023-04-24 18:55:18,172: WARNING/MainProcess] Message: 'Task handler raised error: %r'
Arguments: (ValueError('not enough values to unpack (expected 3, got 0)'),)
[2023-04-24 18:55:18,458: INFO/MainProcess] Task base.tasks.send_the_email[6763f63c-d194-42aa-9ed6-72cc68e0f9d7] received
[2023-04-24 18:55:18,469: WARNING/MainProcess] --- Logging error ---
[2023-04-24 18:55:18,473: WARNING/MainProcess] Traceback (most recent call last):
[2023-04-24 18:55:18,473: WARNING/MainProcess]   File "C:\Users\User\AppData\Local\Programs\Python\Python311\Lib\logging\__init__.py", line 1110, in emit
    msg = self.format(record)
          ^^^^^^^^^^^^^^^^^^^
[2023-04-24 18:55:18,473: WARNING/MainProcess]   File "C:\Users\User\AppData\Local\Programs\Python\Python311\Lib\logging\__init__.py", line 953, in format
    return fmt.format(record)
           ^^^^^^^^^^^^^^^^^^
[2023-04-24 18:55:18,473: WARNING/MainProcess]   File "C:\Users\User\AppData\Local\Programs\Python\Python311\Lib\site-packages\celery\utils\log.py", line 146, in format
    msg = super().format(record)
          ^^^^^^^^^^^^^^^^^^^^^^
[2023-04-24 18:55:18,473: WARNING/MainProcess]   File "C:\Users\User\AppData\Local\Programs\Python\Python311\Lib\logging\__init__.py", line 695, in format
    record.exc_text = self.formatException(record.exc_info)
                      ^^^^^^^^^^^^^^^^^^^^^^^^^^^^^^^^^^^^^
[2023-04-24 18:55:18,473: WARNING/MainProcess]   File "C:\Users\User\AppData\Local\Programs\Python\Python311\Lib\site-packages\celery\utils\log.py", line 142, in formatException
    r = super().formatException(ei)
        ^^^^^^^^^^^^^^^^^^^^^^^^^^^
[2023-04-24 18:55:18,473: WARNING/MainProcess]   File "C:\Users\User\AppData\Local\Programs\Python\Python311\Lib\logging\__init__.py", line 645, in formatException
    traceback.print_exception(ei[0], ei[1], tb, None, sio)
[2023-04-24 18:55:18,473: WARNING/MainProcess]   File "C:\Users\User\AppData\Local\Programs\Python\Python311\Lib\traceback.py", line 124, in print_exception
    te = TracebackException(type(value), value, tb, limit=limit, compact=True)
         ^^^^^^^^^^^^^^^^^^^^^^^^^^^^^^^^^^^^^^^^^^^^^^^^^^^^^^^^^^^^^^^^^^^^^
[2023-04-24 18:55:18,473: WARNING/MainProcess]   File "C:\Users\User\AppData\Local\Programs\Python\Python311\Lib\traceback.py", line 690, in __init__
    self.stack = StackSummary._extract_from_extended_frame_gen(
                 ^^^^^^^^^^^^^^^^^^^^^^^^^^^^^^^^^^^^^^^^^^^^^^
[2023-04-24 18:55:18,473: WARNING/MainProcess]   File "C:\Users\User\AppData\Local\Programs\Python\Python311\Lib\traceback.py", line 416, in _extract_from_extended_frame_gen
    for f, (lineno, end_lineno, colno, end_colno) in frame_gen:
[2023-04-24 18:55:18,473: WARNING/MainProcess]   File "C:\Users\User\AppData\Local\Programs\Python\Python311\Lib\traceback.py", line 353, in _walk_tb_with_full_positions
    positions = _get_code_position(tb.tb_frame.f_code, tb.tb_lasti)
                ^^^^^^^^^^^^^^^^^^^^^^^^^^^^^^^^^^^^^^^^^^^^^^^^^^^
[2023-04-24 18:55:18,473: WARNING/MainProcess]   File "C:\Users\User\AppData\Local\Programs\Python\Python311\Lib\traceback.py", line 366, in _get_code_position
    positions_gen = code.co_positions()
                    ^^^^^^^^^^^^^^^^^
[2023-04-24 18:55:18,473: WARNING/MainProcess] AttributeError: '_Code' object has no attribute 'co_positions'
[2023-04-24 18:55:18,473: WARNING/MainProcess] Call stack:
[2023-04-24 18:55:18,473: WARNING/MainProcess]   File "C:\Users\User\AppData\Local\Programs\Python\Python311\Lib\threading.py", line 995, in _bootstrap
    self._bootstrap_inner()
[2023-04-24 18:55:18,473: WARNING/MainProcess]   File "C:\Users\User\AppData\Local\Programs\Python\Python311\Lib\threading.py", line 1038, in _bootstrap_inner
    self.run()
[2023-04-24 18:55:18,473: WARNING/MainProcess]   File "C:\Users\User\AppData\Local\Programs\Python\Python311\Lib\site-packages\billiard\pool.py", line 504, in run
    return self.body()
[2023-04-24 18:55:18,473: WARNING/MainProcess]   File "C:\Users\User\AppData\Local\Programs\Python\Python311\Lib\site-packages\billiard\pool.py", line 899, in body
    for _ in self._process_result(1.0):  # blocking
[2023-04-24 18:55:18,473: WARNING/MainProcess]   File "C:\Users\User\AppData\Local\Programs\Python\Python311\Lib\site-packages\billiard\pool.py", line 878, in _process_result
    on_state_change(task)
[2023-04-24 18:55:18,473: WARNING/MainProcess]   File "C:\Users\User\AppData\Local\Programs\Python\Python311\Lib\site-packages\billiard\pool.py", line 853, in on_state_change
    state_handlers[state](*args)
[2023-04-24 18:55:18,473: WARNING/MainProcess]   File "C:\Users\User\AppData\Local\Programs\Python\Python311\Lib\site-packages\billiard\pool.py", line 835, in on_ready
    item._set(i, obj)
[2023-04-24 18:55:18,473: WARNING/MainProcess]   File "C:\Users\User\AppData\Local\Programs\Python\Python311\Lib\site-packages\billiard\pool.py", line 1828, in _set
    self.safe_apply_callback(
[2023-04-24 18:55:18,473: WARNING/MainProcess]   File "C:\Users\User\AppData\Local\Programs\Python\Python311\Lib\site-packages\billiard\pool.py", line 1796, in safe_apply_callback
    fun(*args, **kwargs)
[2023-04-24 18:55:18,473: WARNING/MainProcess]   File "C:\Users\User\AppData\Local\Programs\Python\Python311\Lib\site-packages\celery\worker\request.py", line 596, in on_failure
    error('Task handler raised error: %r', exc,
[2023-04-24 18:55:18,473: WARNING/MainProcess] Message: 'Task handler raised error: %r'
Arguments: (ValueError('not enough values to unpack (expected 3, got 0)'),)
[2023-04-24 18:55:18,598: INFO/MainProcess] Task base.tasks.send_the_email[624251b9-b293-40c6-bb92-f0c5fcab01c0] received
[2023-04-24 18:55:18,598: WARNING/MainProcess] --- Logging error ---
[2023-04-24 18:55:18,598: WARNING/MainProcess] Traceback (most recent call last):
[2023-04-24 18:55:18,598: WARNING/MainProcess]   File "C:\Users\User\AppData\Local\Programs\Python\Python311\Lib\logging\__init__.py", line 1110, in emit
    msg = self.format(record)
          ^^^^^^^^^^^^^^^^^^^
[2023-04-24 18:55:18,598: WARNING/MainProcess]   File "C:\Users\User\AppData\Local\Programs\Python\Python311\Lib\logging\__init__.py", line 953, in format
    return fmt.format(record)
           ^^^^^^^^^^^^^^^^^^
[2023-04-24 18:55:18,598: WARNING/MainProcess]   File "C:\Users\User\AppData\Local\Programs\Python\Python311\Lib\site-packages\celery\utils\log.py", line 146, in format
    msg = super().format(record)
          ^^^^^^^^^^^^^^^^^^^^^^
[2023-04-24 18:55:18,598: WARNING/MainProcess]   File "C:\Users\User\AppData\Local\Programs\Python\Python311\Lib\logging\__init__.py", line 695, in format
    record.exc_text = self.formatException(record.exc_info)
                      ^^^^^^^^^^^^^^^^^^^^^^^^^^^^^^^^^^^^^
[2023-04-24 18:55:18,598: WARNING/MainProcess]   File "C:\Users\User\AppData\Local\Programs\Python\Python311\Lib\site-packages\celery\utils\log.py", line 142, in formatException
    r = super().formatException(ei)
        ^^^^^^^^^^^^^^^^^^^^^^^^^^^
[2023-04-24 18:55:18,598: WARNING/MainProcess]   File "C:\Users\User\AppData\Local\Programs\Python\Python311\Lib\logging\__init__.py", line 645, in formatException
    traceback.print_exception(ei[0], ei[1], tb, None, sio)
[2023-04-24 18:55:18,598: WARNING/MainProcess]   File "C:\Users\User\AppData\Local\Programs\Python\Python311\Lib\traceback.py", line 124, in print_exception
    te = TracebackException(type(value), value, tb, limit=limit, compact=True)
         ^^^^^^^^^^^^^^^^^^^^^^^^^^^^^^^^^^^^^^^^^^^^^^^^^^^^^^^^^^^^^^^^^^^^^
[2023-04-24 18:55:18,598: WARNING/MainProcess]   File "C:\Users\User\AppData\Local\Programs\Python\Python311\Lib\traceback.py", line 690, in __init__
    self.stack = StackSummary._extract_from_extended_frame_gen(
                 ^^^^^^^^^^^^^^^^^^^^^^^^^^^^^^^^^^^^^^^^^^^^^^
[2023-04-24 18:55:18,598: WARNING/MainProcess]   File "C:\Users\User\AppData\Local\Programs\Python\Python311\Lib\traceback.py", line 416, in _extract_from_extended_frame_gen
    for f, (lineno, end_lineno, colno, end_colno) in frame_gen:
[2023-04-24 18:55:18,598: WARNING/MainProcess]   File "C:\Users\User\AppData\Local\Programs\Python\Python311\Lib\traceback.py", line 353, in _walk_tb_with_full_positions
    positions = _get_code_position(tb.tb_frame.f_code, tb.tb_lasti)
                ^^^^^^^^^^^^^^^^^^^^^^^^^^^^^^^^^^^^^^^^^^^^^^^^^^^
[2023-04-24 18:55:18,598: WARNING/MainProcess]   File "C:\Users\User\AppData\Local\Programs\Python\Python311\Lib\traceback.py", line 366, in _get_code_position
    positions_gen = code.co_positions()
                    ^^^^^^^^^^^^^^^^^
[2023-04-24 18:55:18,598: WARNING/MainProcess] AttributeError: '_Code' object has no attribute 'co_positions'
[2023-04-24 18:55:18,598: WARNING/MainProcess] Call stack:
[2023-04-24 18:55:18,614: WARNING/MainProcess]   File "C:\Users\User\AppData\Local\Programs\Python\Python311\Lib\threading.py", line 995, in _bootstrap
    self._bootstrap_inner()
[2023-04-24 18:55:18,614: WARNING/MainProcess]   File "C:\Users\User\AppData\Local\Programs\Python\Python311\Lib\threading.py", line 1038, in _bootstrap_inner
    self.run()
[2023-04-24 18:55:18,614: WARNING/MainProcess]   File "C:\Users\User\AppData\Local\Programs\Python\Python311\Lib\site-packages\billiard\pool.py", line 504, in run
    return self.body()
[2023-04-24 18:55:18,614: WARNING/MainProcess]   File "C:\Users\User\AppData\Local\Programs\Python\Python311\Lib\site-packages\billiard\pool.py", line 899, in body
    for _ in self._process_result(1.0):  # blocking
[2023-04-24 18:55:18,614: WARNING/MainProcess]   File "C:\Users\User\AppData\Local\Programs\Python\Python311\Lib\site-packages\billiard\pool.py", line 878, in _process_result
    on_state_change(task)
[2023-04-24 18:55:18,614: WARNING/MainProcess]   File "C:\Users\User\AppData\Local\Programs\Python\Python311\Lib\site-packages\billiard\pool.py", line 853, in on_state_change
    state_handlers[state](*args)
[2023-04-24 18:55:18,614: WARNING/MainProcess]   File "C:\Users\User\AppData\Local\Programs\Python\Python311\Lib\site-packages\billiard\pool.py", line 835, in on_ready
    item._set(i, obj)
[2023-04-24 18:55:18,614: WARNING/MainProcess]   File "C:\Users\User\AppData\Local\Programs\Python\Python311\Lib\site-packages\billiard\pool.py", line 1828, in _set
    self.safe_apply_callback(
[2023-04-24 18:55:18,614: WARNING/MainProcess]   File "C:\Users\User\AppData\Local\Programs\Python\Python311\Lib\site-packages\billiard\pool.py", line 1796, in safe_apply_callback
    fun(*args, **kwargs)
[2023-04-24 18:55:18,614: WARNING/MainProcess]   File "C:\Users\User\AppData\Local\Programs\Python\Python311\Lib\site-packages\celery\worker\request.py", line 596, in on_failure
    error('Task handler raised error: %r', exc,
[2023-04-24 18:55:18,614: WARNING/MainProcess] Message: 'Task handler raised error: %r'
Arguments: (ValueError('not enough values to unpack (expected 3, got 0)'),)
[2023-04-24 18:55:18,883: INFO/MainProcess] Task base.tasks.send_the_email[b7624164-3e56-45df-9a9f-50bd0abfedf3] received
[2023-04-24 18:55:18,883: WARNING/MainProcess] --- Logging error ---
[2023-04-24 18:55:18,883: WARNING/MainProcess] Traceback (most recent call last):
[2023-04-24 18:55:18,883: WARNING/MainProcess]   File "C:\Users\User\AppData\Local\Programs\Python\Python311\Lib\logging\__init__.py", line 1110, in emit
    msg = self.format(record)
          ^^^^^^^^^^^^^^^^^^^
[2023-04-24 18:55:18,883: WARNING/MainProcess]   File "C:\Users\User\AppData\Local\Programs\Python\Python311\Lib\logging\__init__.py", line 953, in format
    return fmt.format(record)
           ^^^^^^^^^^^^^^^^^^
[2023-04-24 18:55:18,883: WARNING/MainProcess]   File "C:\Users\User\AppData\Local\Programs\Python\Python311\Lib\site-packages\celery\utils\log.py", line 146, in format
    msg = super().format(record)
          ^^^^^^^^^^^^^^^^^^^^^^
[2023-04-24 18:55:18,883: WARNING/MainProcess]   File "C:\Users\User\AppData\Local\Programs\Python\Python311\Lib\logging\__init__.py", line 695, in format
    record.exc_text = self.formatException(record.exc_info)
                      ^^^^^^^^^^^^^^^^^^^^^^^^^^^^^^^^^^^^^
[2023-04-24 18:55:18,883: WARNING/MainProcess]   File "C:\Users\User\AppData\Local\Programs\Python\Python311\Lib\site-packages\celery\utils\log.py", line 142, in formatException
    r = super().formatException(ei)
        ^^^^^^^^^^^^^^^^^^^^^^^^^^^
[2023-04-24 18:55:18,883: WARNING/MainProcess]   File "C:\Users\User\AppData\Local\Programs\Python\Python311\Lib\logging\__init__.py", line 645, in formatException
    traceback.print_exception(ei[0], ei[1], tb, None, sio)
[2023-04-24 18:55:18,883: WARNING/MainProcess]   File "C:\Users\User\AppData\Local\Programs\Python\Python311\Lib\traceback.py", line 124, in print_exception
    te = TracebackException(type(value), value, tb, limit=limit, compact=True)
         ^^^^^^^^^^^^^^^^^^^^^^^^^^^^^^^^^^^^^^^^^^^^^^^^^^^^^^^^^^^^^^^^^^^^^
[2023-04-24 18:55:18,883: WARNING/MainProcess]   File "C:\Users\User\AppData\Local\Programs\Python\Python311\Lib\traceback.py", line 690, in __init__
    self.stack = StackSummary._extract_from_extended_frame_gen(
                 ^^^^^^^^^^^^^^^^^^^^^^^^^^^^^^^^^^^^^^^^^^^^^^
[2023-04-24 18:55:18,883: WARNING/MainProcess]   File "C:\Users\User\AppData\Local\Programs\Python\Python311\Lib\traceback.py", line 416, in _extract_from_extended_frame_gen
    for f, (lineno, end_lineno, colno, end_colno) in frame_gen:
[2023-04-24 18:55:18,883: WARNING/MainProcess]   File "C:\Users\User\AppData\Local\Programs\Python\Python311\Lib\traceback.py", line 353, in _walk_tb_with_full_positions
    positions = _get_code_position(tb.tb_frame.f_code, tb.tb_lasti)
                ^^^^^^^^^^^^^^^^^^^^^^^^^^^^^^^^^^^^^^^^^^^^^^^^^^^
[2023-04-24 18:55:18,883: WARNING/MainProcess]   File "C:\Users\User\AppData\Local\Programs\Python\Python311\Lib\traceback.py", line 366, in _get_code_position
    positions_gen = code.co_positions()
                    ^^^^^^^^^^^^^^^^^
[2023-04-24 18:55:18,883: WARNING/MainProcess] AttributeError: '_Code' object has no attribute 'co_positions'
[2023-04-24 18:55:18,883: WARNING/MainProcess] Call stack:
[2023-04-24 18:55:18,883: WARNING/MainProcess]   File "C:\Users\User\AppData\Local\Programs\Python\Python311\Lib\threading.py", line 995, in _bootstrap
    self._bootstrap_inner()
[2023-04-24 18:55:18,883: WARNING/MainProcess]   File "C:\Users\User\AppData\Local\Programs\Python\Python311\Lib\threading.py", line 1038, in _bootstrap_inner
    self.run()
[2023-04-24 18:55:18,883: WARNING/MainProcess]   File "C:\Users\User\AppData\Local\Programs\Python\Python311\Lib\site-packages\billiard\pool.py", line 504, in run
    return self.body()
[2023-04-24 18:55:18,883: WARNING/MainProcess]   File "C:\Users\User\AppData\Local\Programs\Python\Python311\Lib\site-packages\billiard\pool.py", line 899, in body
    for _ in self._process_result(1.0):  # blocking
[2023-04-24 18:55:18,883: WARNING/MainProcess]   File "C:\Users\User\AppData\Local\Programs\Python\Python311\Lib\site-packages\billiard\pool.py", line 878, in _process_result
    on_state_change(task)
[2023-04-24 18:55:18,883: WARNING/MainProcess]   File "C:\Users\User\AppData\Local\Programs\Python\Python311\Lib\site-packages\billiard\pool.py", line 853, in on_state_change
    state_handlers[state](*args)
[2023-04-24 18:55:18,883: WARNING/MainProcess]   File "C:\Users\User\AppData\Local\Programs\Python\Python311\Lib\site-packages\billiard\pool.py", line 835, in on_ready
    item._set(i, obj)
[2023-04-24 18:55:18,883: WARNING/MainProcess]   File "C:\Users\User\AppData\Local\Programs\Python\Python311\Lib\site-packages\billiard\pool.py", line 1828, in _set
    self.safe_apply_callback(
[2023-04-24 18:55:18,883: WARNING/MainProcess]   File "C:\Users\User\AppData\Local\Programs\Python\Python311\Lib\site-packages\billiard\pool.py", line 1796, in safe_apply_callback
    fun(*args, **kwargs)
[2023-04-24 18:55:18,883: WARNING/MainProcess]   File "C:\Users\User\AppData\Local\Programs\Python\Python311\Lib\site-packages\celery\worker\request.py", line 596, in on_failure
    error('Task handler raised error: %r', exc,
[2023-04-24 18:55:18,883: WARNING/MainProcess] Message: 'Task handler raised error: %r'
Arguments: (ValueError('not enough values to unpack (expected 3, got 0)'),)
[2023-04-24 19:01:41,230: INFO/MainProcess] Task base.tasks.send_the_email[1f9a31af-b597-4bf0-8a0b-a8f49ade973c] received
[2023-04-24 19:01:41,238: WARNING/MainProcess] --- Logging error ---
[2023-04-24 19:01:41,238: WARNING/MainProcess] Traceback (most recent call last):
[2023-04-24 19:01:41,238: WARNING/MainProcess]   File "C:\Users\User\AppData\Local\Programs\Python\Python311\Lib\logging\__init__.py", line 1110, in emit
    msg = self.format(record)
          ^^^^^^^^^^^^^^^^^^^
[2023-04-24 19:01:41,238: WARNING/MainProcess]   File "C:\Users\User\AppData\Local\Programs\Python\Python311\Lib\logging\__init__.py", line 953, in format
    return fmt.format(record)
           ^^^^^^^^^^^^^^^^^^
[2023-04-24 19:01:41,238: WARNING/MainProcess]   File "C:\Users\User\AppData\Local\Programs\Python\Python311\Lib\site-packages\celery\utils\log.py", line 146, in format
    msg = super().format(record)
          ^^^^^^^^^^^^^^^^^^^^^^
[2023-04-24 19:01:41,238: WARNING/MainProcess]   File "C:\Users\User\AppData\Local\Programs\Python\Python311\Lib\logging\__init__.py", line 695, in format
    record.exc_text = self.formatException(record.exc_info)
                      ^^^^^^^^^^^^^^^^^^^^^^^^^^^^^^^^^^^^^
[2023-04-24 19:01:41,238: WARNING/MainProcess]   File "C:\Users\User\AppData\Local\Programs\Python\Python311\Lib\site-packages\celery\utils\log.py", line 142, in formatException
    r = super().formatException(ei)
        ^^^^^^^^^^^^^^^^^^^^^^^^^^^
[2023-04-24 19:01:41,238: WARNING/MainProcess]   File "C:\Users\User\AppData\Local\Programs\Python\Python311\Lib\logging\__init__.py", line 645, in formatException
    traceback.print_exception(ei[0], ei[1], tb, None, sio)
[2023-04-24 19:01:41,238: WARNING/MainProcess]   File "C:\Users\User\AppData\Local\Programs\Python\Python311\Lib\traceback.py", line 124, in print_exception
    te = TracebackException(type(value), value, tb, limit=limit, compact=True)
         ^^^^^^^^^^^^^^^^^^^^^^^^^^^^^^^^^^^^^^^^^^^^^^^^^^^^^^^^^^^^^^^^^^^^^
[2023-04-24 19:01:41,238: WARNING/MainProcess]   File "C:\Users\User\AppData\Local\Programs\Python\Python311\Lib\traceback.py", line 690, in __init__
    self.stack = StackSummary._extract_from_extended_frame_gen(
                 ^^^^^^^^^^^^^^^^^^^^^^^^^^^^^^^^^^^^^^^^^^^^^^
[2023-04-24 19:01:41,238: WARNING/MainProcess]   File "C:\Users\User\AppData\Local\Programs\Python\Python311\Lib\traceback.py", line 416, in _extract_from_extended_frame_gen
    for f, (lineno, end_lineno, colno, end_colno) in frame_gen:
[2023-04-24 19:01:41,238: WARNING/MainProcess]   File "C:\Users\User\AppData\Local\Programs\Python\Python311\Lib\traceback.py", line 353, in _walk_tb_with_full_positions
    positions = _get_code_position(tb.tb_frame.f_code, tb.tb_lasti)
                ^^^^^^^^^^^^^^^^^^^^^^^^^^^^^^^^^^^^^^^^^^^^^^^^^^^
[2023-04-24 19:01:41,238: WARNING/MainProcess]   File "C:\Users\User\AppData\Local\Programs\Python\Python311\Lib\traceback.py", line 366, in _get_code_position
    positions_gen = code.co_positions()
                    ^^^^^^^^^^^^^^^^^
[2023-04-24 19:01:41,238: WARNING/MainProcess] AttributeError: '_Code' object has no attribute 'co_positions'
[2023-04-24 19:01:41,238: WARNING/MainProcess] Call stack:
[2023-04-24 19:01:41,246: WARNING/MainProcess]   File "C:\Users\User\AppData\Local\Programs\Python\Python311\Lib\threading.py", line 995, in _bootstrap
    self._bootstrap_inner()
[2023-04-24 19:01:41,246: WARNING/MainProcess]   File "C:\Users\User\AppData\Local\Programs\Python\Python311\Lib\threading.py", line 1038, in _bootstrap_inner
    self.run()
[2023-04-24 19:01:41,246: WARNING/MainProcess]   File "C:\Users\User\AppData\Local\Programs\Python\Python311\Lib\site-packages\billiard\pool.py", line 504, in run
    return self.body()
[2023-04-24 19:01:41,246: WARNING/MainProcess]   File "C:\Users\User\AppData\Local\Programs\Python\Python311\Lib\site-packages\billiard\pool.py", line 899, in body
    for _ in self._process_result(1.0):  # blocking
[2023-04-24 19:01:41,246: WARNING/MainProcess]   File "C:\Users\User\AppData\Local\Programs\Python\Python311\Lib\site-packages\billiard\pool.py", line 878, in _process_result
    on_state_change(task)
[2023-04-24 19:01:41,246: WARNING/MainProcess]   File "C:\Users\User\AppData\Local\Programs\Python\Python311\Lib\site-packages\billiard\pool.py", line 853, in on_state_change
    state_handlers[state](*args)
[2023-04-24 19:01:41,246: WARNING/MainProcess]   File "C:\Users\User\AppData\Local\Programs\Python\Python311\Lib\site-packages\billiard\pool.py", line 835, in on_ready
    item._set(i, obj)
[2023-04-24 19:01:41,246: WARNING/MainProcess]   File "C:\Users\User\AppData\Local\Programs\Python\Python311\Lib\site-packages\billiard\pool.py", line 1828, in _set
    self.safe_apply_callback(
[2023-04-24 19:01:41,246: WARNING/MainProcess]   File "C:\Users\User\AppData\Local\Programs\Python\Python311\Lib\site-packages\billiard\pool.py", line 1796, in safe_apply_callback
    fun(*args, **kwargs)
[2023-04-24 19:01:41,246: WARNING/MainProcess]   File "C:\Users\User\AppData\Local\Programs\Python\Python311\Lib\site-packages\celery\worker\request.py", line 596, in on_failure
    error('Task handler raised error: %r', exc,
[2023-04-24 19:01:41,246: WARNING/MainProcess] Message: 'Task handler raised error: %r'
Arguments: (ValueError('not enough values to unpack (expected 3, got 0)'),)
[2023-04-24 19:04:45,188: INFO/MainProcess] Task base.tasks.send_the_email[725573ed-419e-4028-b1f5-a7bae167c3bf] received
[2023-04-24 19:04:45,193: WARNING/MainProcess] --- Logging error ---
[2023-04-24 19:04:45,193: WARNING/MainProcess] Traceback (most recent call last):
[2023-04-24 19:04:45,193: WARNING/MainProcess]   File "C:\Users\User\AppData\Local\Programs\Python\Python311\Lib\logging\__init__.py", line 1110, in emit
    msg = self.format(record)
          ^^^^^^^^^^^^^^^^^^^
[2023-04-24 19:04:45,193: WARNING/MainProcess]   File "C:\Users\User\AppData\Local\Programs\Python\Python311\Lib\logging\__init__.py", line 953, in format
    return fmt.format(record)
           ^^^^^^^^^^^^^^^^^^
[2023-04-24 19:04:45,193: WARNING/MainProcess]   File "C:\Users\User\AppData\Local\Programs\Python\Python311\Lib\site-packages\celery\utils\log.py", line 146, in format
    msg = super().format(record)
          ^^^^^^^^^^^^^^^^^^^^^^
[2023-04-24 19:04:45,193: WARNING/MainProcess]   File "C:\Users\User\AppData\Local\Programs\Python\Python311\Lib\logging\__init__.py", line 695, in format
    record.exc_text = self.formatException(record.exc_info)
                      ^^^^^^^^^^^^^^^^^^^^^^^^^^^^^^^^^^^^^
[2023-04-24 19:04:45,193: WARNING/MainProcess]   File "C:\Users\User\AppData\Local\Programs\Python\Python311\Lib\site-packages\celery\utils\log.py", line 142, in formatException
    r = super().formatException(ei)
        ^^^^^^^^^^^^^^^^^^^^^^^^^^^
[2023-04-24 19:04:45,193: WARNING/MainProcess]   File "C:\Users\User\AppData\Local\Programs\Python\Python311\Lib\logging\__init__.py", line 645, in formatException
    traceback.print_exception(ei[0], ei[1], tb, None, sio)
[2023-04-24 19:04:45,193: WARNING/MainProcess]   File "C:\Users\User\AppData\Local\Programs\Python\Python311\Lib\traceback.py", line 124, in print_exception
    te = TracebackException(type(value), value, tb, limit=limit, compact=True)
         ^^^^^^^^^^^^^^^^^^^^^^^^^^^^^^^^^^^^^^^^^^^^^^^^^^^^^^^^^^^^^^^^^^^^^
[2023-04-24 19:04:45,193: WARNING/MainProcess]   File "C:\Users\User\AppData\Local\Programs\Python\Python311\Lib\traceback.py", line 690, in __init__
    self.stack = StackSummary._extract_from_extended_frame_gen(
                 ^^^^^^^^^^^^^^^^^^^^^^^^^^^^^^^^^^^^^^^^^^^^^^
[2023-04-24 19:04:45,193: WARNING/MainProcess]   File "C:\Users\User\AppData\Local\Programs\Python\Python311\Lib\traceback.py", line 416, in _extract_from_extended_frame_gen
    for f, (lineno, end_lineno, colno, end_colno) in frame_gen:
[2023-04-24 19:04:45,193: WARNING/MainProcess]   File "C:\Users\User\AppData\Local\Programs\Python\Python311\Lib\traceback.py", line 353, in _walk_tb_with_full_positions
    positions = _get_code_position(tb.tb_frame.f_code, tb.tb_lasti)
                ^^^^^^^^^^^^^^^^^^^^^^^^^^^^^^^^^^^^^^^^^^^^^^^^^^^
[2023-04-24 19:04:45,193: WARNING/MainProcess]   File "C:\Users\User\AppData\Local\Programs\Python\Python311\Lib\traceback.py", line 366, in _get_code_position
    positions_gen = code.co_positions()
                    ^^^^^^^^^^^^^^^^^
[2023-04-24 19:04:45,193: WARNING/MainProcess] AttributeError: '_Code' object has no attribute 'co_positions'
[2023-04-24 19:04:45,193: WARNING/MainProcess] Call stack:
[2023-04-24 19:04:45,201: WARNING/MainProcess]   File "C:\Users\User\AppData\Local\Programs\Python\Python311\Lib\threading.py", line 995, in _bootstrap
    self._bootstrap_inner()
[2023-04-24 19:04:45,201: WARNING/MainProcess]   File "C:\Users\User\AppData\Local\Programs\Python\Python311\Lib\threading.py", line 1038, in _bootstrap_inner
    self.run()
[2023-04-24 19:04:45,201: WARNING/MainProcess]   File "C:\Users\User\AppData\Local\Programs\Python\Python311\Lib\site-packages\billiard\pool.py", line 504, in run
    return self.body()
[2023-04-24 19:04:45,201: WARNING/MainProcess]   File "C:\Users\User\AppData\Local\Programs\Python\Python311\Lib\site-packages\billiard\pool.py", line 899, in body
    for _ in self._process_result(1.0):  # blocking
[2023-04-24 19:04:45,201: WARNING/MainProcess]   File "C:\Users\User\AppData\Local\Programs\Python\Python311\Lib\site-packages\billiard\pool.py", line 878, in _process_result
    on_state_change(task)
[2023-04-24 19:04:45,201: WARNING/MainProcess]   File "C:\Users\User\AppData\Local\Programs\Python\Python311\Lib\site-packages\billiard\pool.py", line 853, in on_state_change
    state_handlers[state](*args)
[2023-04-24 19:04:45,201: WARNING/MainProcess]   File "C:\Users\User\AppData\Local\Programs\Python\Python311\Lib\site-packages\billiard\pool.py", line 835, in on_ready
    item._set(i, obj)
[2023-04-24 19:04:45,201: WARNING/MainProcess]   File "C:\Users\User\AppData\Local\Programs\Python\Python311\Lib\site-packages\billiard\pool.py", line 1828, in _set
    self.safe_apply_callback(
[2023-04-24 19:04:45,201: WARNING/MainProcess]   File "C:\Users\User\AppData\Local\Programs\Python\Python311\Lib\site-packages\billiard\pool.py", line 1796, in safe_apply_callback
    fun(*args, **kwargs)
[2023-04-24 19:04:45,201: WARNING/MainProcess]   File "C:\Users\User\AppData\Local\Programs\Python\Python311\Lib\site-packages\celery\worker\request.py", line 596, in on_failure
    error('Task handler raised error: %r', exc,
[2023-04-24 19:04:45,201: WARNING/MainProcess] Message: 'Task handler raised error: %r'
Arguments: (ValueError('not enough values to unpack (expected 3, got 0)'),)
[2023-04-24 19:11:25,990: INFO/MainProcess] Task base.tasks.send_the_email[cb1b5e33-138c-4b0c-9fa0-b17ad07c6bd0] received
[2023-04-24 19:11:25,997: WARNING/MainProcess] --- Logging error ---
[2023-04-24 19:11:25,997: WARNING/MainProcess] Traceback (most recent call last):
[2023-04-24 19:11:25,997: WARNING/MainProcess]   File "C:\Users\User\AppData\Local\Programs\Python\Python311\Lib\logging\__init__.py", line 1110, in emit
    msg = self.format(record)
          ^^^^^^^^^^^^^^^^^^^
[2023-04-24 19:11:25,997: WARNING/MainProcess]   File "C:\Users\User\AppData\Local\Programs\Python\Python311\Lib\logging\__init__.py", line 953, in format
    return fmt.format(record)
           ^^^^^^^^^^^^^^^^^^
[2023-04-24 19:11:25,997: WARNING/MainProcess]   File "C:\Users\User\AppData\Local\Programs\Python\Python311\Lib\site-packages\celery\utils\log.py", line 146, in format
    msg = super().format(record)
          ^^^^^^^^^^^^^^^^^^^^^^
[2023-04-24 19:11:25,997: WARNING/MainProcess]   File "C:\Users\User\AppData\Local\Programs\Python\Python311\Lib\logging\__init__.py", line 695, in format
    record.exc_text = self.formatException(record.exc_info)
                      ^^^^^^^^^^^^^^^^^^^^^^^^^^^^^^^^^^^^^
[2023-04-24 19:11:25,997: WARNING/MainProcess]   File "C:\Users\User\AppData\Local\Programs\Python\Python311\Lib\site-packages\celery\utils\log.py", line 142, in formatException
    r = super().formatException(ei)
        ^^^^^^^^^^^^^^^^^^^^^^^^^^^
[2023-04-24 19:11:25,997: WARNING/MainProcess]   File "C:\Users\User\AppData\Local\Programs\Python\Python311\Lib\logging\__init__.py", line 645, in formatException
    traceback.print_exception(ei[0], ei[1], tb, None, sio)
[2023-04-24 19:11:25,997: WARNING/MainProcess]   File "C:\Users\User\AppData\Local\Programs\Python\Python311\Lib\traceback.py", line 124, in print_exception
    te = TracebackException(type(value), value, tb, limit=limit, compact=True)
         ^^^^^^^^^^^^^^^^^^^^^^^^^^^^^^^^^^^^^^^^^^^^^^^^^^^^^^^^^^^^^^^^^^^^^
[2023-04-24 19:11:25,997: WARNING/MainProcess]   File "C:\Users\User\AppData\Local\Programs\Python\Python311\Lib\traceback.py", line 690, in __init__
    self.stack = StackSummary._extract_from_extended_frame_gen(
                 ^^^^^^^^^^^^^^^^^^^^^^^^^^^^^^^^^^^^^^^^^^^^^^
[2023-04-24 19:11:25,997: WARNING/MainProcess]   File "C:\Users\User\AppData\Local\Programs\Python\Python311\Lib\traceback.py", line 416, in _extract_from_extended_frame_gen
    for f, (lineno, end_lineno, colno, end_colno) in frame_gen:
[2023-04-24 19:11:25,997: WARNING/MainProcess]   File "C:\Users\User\AppData\Local\Programs\Python\Python311\Lib\traceback.py", line 353, in _walk_tb_with_full_positions
    positions = _get_code_position(tb.tb_frame.f_code, tb.tb_lasti)
                ^^^^^^^^^^^^^^^^^^^^^^^^^^^^^^^^^^^^^^^^^^^^^^^^^^^
[2023-04-24 19:11:25,997: WARNING/MainProcess]   File "C:\Users\User\AppData\Local\Programs\Python\Python311\Lib\traceback.py", line 366, in _get_code_position
    positions_gen = code.co_positions()
                    ^^^^^^^^^^^^^^^^^
[2023-04-24 19:11:25,997: WARNING/MainProcess] AttributeError: '_Code' object has no attribute 'co_positions'
[2023-04-24 19:11:25,997: WARNING/MainProcess] Call stack:
[2023-04-24 19:11:25,997: WARNING/MainProcess]   File "C:\Users\User\AppData\Local\Programs\Python\Python311\Lib\threading.py", line 995, in _bootstrap
    self._bootstrap_inner()
[2023-04-24 19:11:25,997: WARNING/MainProcess]   File "C:\Users\User\AppData\Local\Programs\Python\Python311\Lib\threading.py", line 1038, in _bootstrap_inner
    self.run()
[2023-04-24 19:11:25,997: WARNING/MainProcess]   File "C:\Users\User\AppData\Local\Programs\Python\Python311\Lib\site-packages\billiard\pool.py", line 504, in run
    return self.body()
[2023-04-24 19:11:25,997: WARNING/MainProcess]   File "C:\Users\User\AppData\Local\Programs\Python\Python311\Lib\site-packages\billiard\pool.py", line 899, in body
    for _ in self._process_result(1.0):  # blocking
[2023-04-24 19:11:25,997: WARNING/MainProcess]   File "C:\Users\User\AppData\Local\Programs\Python\Python311\Lib\site-packages\billiard\pool.py", line 878, in _process_result
    on_state_change(task)
[2023-04-24 19:11:26,012: WARNING/MainProcess]   File "C:\Users\User\AppData\Local\Programs\Python\Python311\Lib\site-packages\billiard\pool.py", line 853, in on_state_change
    state_handlers[state](*args)
[2023-04-24 19:11:26,012: WARNING/MainProcess]   File "C:\Users\User\AppData\Local\Programs\Python\Python311\Lib\site-packages\billiard\pool.py", line 835, in on_ready
    item._set(i, obj)
[2023-04-24 19:11:26,012: WARNING/MainProcess]   File "C:\Users\User\AppData\Local\Programs\Python\Python311\Lib\site-packages\billiard\pool.py", line 1828, in _set
    self.safe_apply_callback(
[2023-04-24 19:11:26,012: WARNING/MainProcess]   File "C:\Users\User\AppData\Local\Programs\Python\Python311\Lib\site-packages\billiard\pool.py", line 1796, in safe_apply_callback
    fun(*args, **kwargs)
[2023-04-24 19:11:26,012: WARNING/MainProcess]   File "C:\Users\User\AppData\Local\Programs\Python\Python311\Lib\site-packages\celery\worker\request.py", line 596, in on_failure
    error('Task handler raised error: %r', exc,
[2023-04-24 19:11:26,012: WARNING/MainProcess] Message: 'Task handler raised error: %r'
Arguments: (ValueError('not enough values to unpack (expected 3, got 0)'),)
[2023-04-24 19:11:35,160: INFO/MainProcess] Task base.tasks.send_the_email[92b5ea07-a569-4c33-ba78-9032691146da] received
[2023-04-24 19:11:35,160: WARNING/MainProcess] --- Logging error ---
[2023-04-24 19:11:35,160: WARNING/MainProcess] Traceback (most recent call last):
[2023-04-24 19:11:35,160: WARNING/MainProcess]   File "C:\Users\User\AppData\Local\Programs\Python\Python311\Lib\logging\__init__.py", line 1110, in emit
    msg = self.format(record)
          ^^^^^^^^^^^^^^^^^^^
[2023-04-24 19:11:35,160: WARNING/MainProcess]   File "C:\Users\User\AppData\Local\Programs\Python\Python311\Lib\logging\__init__.py", line 953, in format
    return fmt.format(record)
           ^^^^^^^^^^^^^^^^^^
[2023-04-24 19:11:35,160: WARNING/MainProcess]   File "C:\Users\User\AppData\Local\Programs\Python\Python311\Lib\site-packages\celery\utils\log.py", line 146, in format
    msg = super().format(record)
          ^^^^^^^^^^^^^^^^^^^^^^
[2023-04-24 19:11:35,160: WARNING/MainProcess]   File "C:\Users\User\AppData\Local\Programs\Python\Python311\Lib\logging\__init__.py", line 695, in format
    record.exc_text = self.formatException(record.exc_info)
                      ^^^^^^^^^^^^^^^^^^^^^^^^^^^^^^^^^^^^^
[2023-04-24 19:11:35,160: WARNING/MainProcess]   File "C:\Users\User\AppData\Local\Programs\Python\Python311\Lib\site-packages\celery\utils\log.py", line 142, in formatException
    r = super().formatException(ei)
        ^^^^^^^^^^^^^^^^^^^^^^^^^^^
[2023-04-24 19:11:35,160: WARNING/MainProcess]   File "C:\Users\User\AppData\Local\Programs\Python\Python311\Lib\logging\__init__.py", line 645, in formatException
    traceback.print_exception(ei[0], ei[1], tb, None, sio)
[2023-04-24 19:11:35,160: WARNING/MainProcess]   File "C:\Users\User\AppData\Local\Programs\Python\Python311\Lib\traceback.py", line 124, in print_exception
    te = TracebackException(type(value), value, tb, limit=limit, compact=True)
         ^^^^^^^^^^^^^^^^^^^^^^^^^^^^^^^^^^^^^^^^^^^^^^^^^^^^^^^^^^^^^^^^^^^^^
[2023-04-24 19:11:35,160: WARNING/MainProcess]   File "C:\Users\User\AppData\Local\Programs\Python\Python311\Lib\traceback.py", line 690, in __init__
    self.stack = StackSummary._extract_from_extended_frame_gen(
                 ^^^^^^^^^^^^^^^^^^^^^^^^^^^^^^^^^^^^^^^^^^^^^^
[2023-04-24 19:11:35,160: WARNING/MainProcess]   File "C:\Users\User\AppData\Local\Programs\Python\Python311\Lib\traceback.py", line 416, in _extract_from_extended_frame_gen
    for f, (lineno, end_lineno, colno, end_colno) in frame_gen:
[2023-04-24 19:11:35,160: WARNING/MainProcess]   File "C:\Users\User\AppData\Local\Programs\Python\Python311\Lib\traceback.py", line 353, in _walk_tb_with_full_positions
    positions = _get_code_position(tb.tb_frame.f_code, tb.tb_lasti)
                ^^^^^^^^^^^^^^^^^^^^^^^^^^^^^^^^^^^^^^^^^^^^^^^^^^^
[2023-04-24 19:11:35,160: WARNING/MainProcess]   File "C:\Users\User\AppData\Local\Programs\Python\Python311\Lib\traceback.py", line 366, in _get_code_position
    positions_gen = code.co_positions()
                    ^^^^^^^^^^^^^^^^^
[2023-04-24 19:11:35,160: WARNING/MainProcess] AttributeError: '_Code' object has no attribute 'co_positions'
[2023-04-24 19:11:35,160: WARNING/MainProcess] Call stack:
[2023-04-24 19:11:35,160: WARNING/MainProcess]   File "C:\Users\User\AppData\Local\Programs\Python\Python311\Lib\threading.py", line 995, in _bootstrap
    self._bootstrap_inner()
[2023-04-24 19:11:35,160: WARNING/MainProcess]   File "C:\Users\User\AppData\Local\Programs\Python\Python311\Lib\threading.py", line 1038, in _bootstrap_inner
    self.run()
[2023-04-24 19:11:35,160: WARNING/MainProcess]   File "C:\Users\User\AppData\Local\Programs\Python\Python311\Lib\site-packages\billiard\pool.py", line 504, in run
    return self.body()
[2023-04-24 19:11:35,160: WARNING/MainProcess]   File "C:\Users\User\AppData\Local\Programs\Python\Python311\Lib\site-packages\billiard\pool.py", line 899, in body
    for _ in self._process_result(1.0):  # blocking
[2023-04-24 19:11:35,160: WARNING/MainProcess]   File "C:\Users\User\AppData\Local\Programs\Python\Python311\Lib\site-packages\billiard\pool.py", line 878, in _process_result
    on_state_change(task)
[2023-04-24 19:11:35,160: WARNING/MainProcess]   File "C:\Users\User\AppData\Local\Programs\Python\Python311\Lib\site-packages\billiard\pool.py", line 853, in on_state_change
    state_handlers[state](*args)
[2023-04-24 19:11:35,160: WARNING/MainProcess]   File "C:\Users\User\AppData\Local\Programs\Python\Python311\Lib\site-packages\billiard\pool.py", line 835, in on_ready
    item._set(i, obj)
[2023-04-24 19:11:35,160: WARNING/MainProcess]   File "C:\Users\User\AppData\Local\Programs\Python\Python311\Lib\site-packages\billiard\pool.py", line 1828, in _set
    self.safe_apply_callback(
[2023-04-24 19:11:35,160: WARNING/MainProcess]   File "C:\Users\User\AppData\Local\Programs\Python\Python311\Lib\site-packages\billiard\pool.py", line 1796, in safe_apply_callback
    fun(*args, **kwargs)
[2023-04-24 19:11:35,160: WARNING/MainProcess]   File "C:\Users\User\AppData\Local\Programs\Python\Python311\Lib\site-packages\celery\worker\request.py", line 596, in on_failure
    error('Task handler raised error: %r', exc,
[2023-04-24 19:11:35,160: WARNING/MainProcess] Message: 'Task handler raised error: %r'
Arguments: (ValueError('not enough values to unpack (expected 3, got 0)'),)
[2023-04-24 19:11:52,433: INFO/MainProcess] Task base.tasks.send_the_email[34551839-f83b-44d4-80e2-95f2790f5c23] received
[2023-04-24 19:11:52,433: WARNING/MainProcess] --- Logging error ---
[2023-04-24 19:11:52,433: WARNING/MainProcess] Traceback (most recent call last):
[2023-04-24 19:11:52,433: WARNING/MainProcess]   File "C:\Users\User\AppData\Local\Programs\Python\Python311\Lib\logging\__init__.py", line 1110, in emit
    msg = self.format(record)
          ^^^^^^^^^^^^^^^^^^^
[2023-04-24 19:11:52,433: WARNING/MainProcess]   File "C:\Users\User\AppData\Local\Programs\Python\Python311\Lib\logging\__init__.py", line 953, in format
    return fmt.format(record)
           ^^^^^^^^^^^^^^^^^^
[2023-04-24 19:11:52,433: WARNING/MainProcess]   File "C:\Users\User\AppData\Local\Programs\Python\Python311\Lib\site-packages\celery\utils\log.py", line 146, in format
    msg = super().format(record)
          ^^^^^^^^^^^^^^^^^^^^^^
[2023-04-24 19:11:52,433: WARNING/MainProcess]   File "C:\Users\User\AppData\Local\Programs\Python\Python311\Lib\logging\__init__.py", line 695, in format
    record.exc_text = self.formatException(record.exc_info)
                      ^^^^^^^^^^^^^^^^^^^^^^^^^^^^^^^^^^^^^
[2023-04-24 19:11:52,433: WARNING/MainProcess]   File "C:\Users\User\AppData\Local\Programs\Python\Python311\Lib\site-packages\celery\utils\log.py", line 142, in formatException
    r = super().formatException(ei)
        ^^^^^^^^^^^^^^^^^^^^^^^^^^^
[2023-04-24 19:11:52,433: WARNING/MainProcess]   File "C:\Users\User\AppData\Local\Programs\Python\Python311\Lib\logging\__init__.py", line 645, in formatException
    traceback.print_exception(ei[0], ei[1], tb, None, sio)
[2023-04-24 19:11:52,433: WARNING/MainProcess]   File "C:\Users\User\AppData\Local\Programs\Python\Python311\Lib\traceback.py", line 124, in print_exception
    te = TracebackException(type(value), value, tb, limit=limit, compact=True)
         ^^^^^^^^^^^^^^^^^^^^^^^^^^^^^^^^^^^^^^^^^^^^^^^^^^^^^^^^^^^^^^^^^^^^^
[2023-04-24 19:11:52,433: WARNING/MainProcess]   File "C:\Users\User\AppData\Local\Programs\Python\Python311\Lib\traceback.py", line 690, in __init__
    self.stack = StackSummary._extract_from_extended_frame_gen(
                 ^^^^^^^^^^^^^^^^^^^^^^^^^^^^^^^^^^^^^^^^^^^^^^
[2023-04-24 19:11:52,433: WARNING/MainProcess]   File "C:\Users\User\AppData\Local\Programs\Python\Python311\Lib\traceback.py", line 416, in _extract_from_extended_frame_gen
    for f, (lineno, end_lineno, colno, end_colno) in frame_gen:
[2023-04-24 19:11:52,433: WARNING/MainProcess]   File "C:\Users\User\AppData\Local\Programs\Python\Python311\Lib\traceback.py", line 353, in _walk_tb_with_full_positions
    positions = _get_code_position(tb.tb_frame.f_code, tb.tb_lasti)
                ^^^^^^^^^^^^^^^^^^^^^^^^^^^^^^^^^^^^^^^^^^^^^^^^^^^
[2023-04-24 19:11:52,433: WARNING/MainProcess]   File "C:\Users\User\AppData\Local\Programs\Python\Python311\Lib\traceback.py", line 366, in _get_code_position
    positions_gen = code.co_positions()
                    ^^^^^^^^^^^^^^^^^
[2023-04-24 19:11:52,433: WARNING/MainProcess] AttributeError: '_Code' object has no attribute 'co_positions'
[2023-04-24 19:11:52,441: WARNING/MainProcess] Call stack:
[2023-04-24 19:11:52,441: WARNING/MainProcess]   File "C:\Users\User\AppData\Local\Programs\Python\Python311\Lib\threading.py", line 995, in _bootstrap
    self._bootstrap_inner()
[2023-04-24 19:11:52,441: WARNING/MainProcess]   File "C:\Users\User\AppData\Local\Programs\Python\Python311\Lib\threading.py", line 1038, in _bootstrap_inner
    self.run()
[2023-04-24 19:11:52,441: WARNING/MainProcess]   File "C:\Users\User\AppData\Local\Programs\Python\Python311\Lib\site-packages\billiard\pool.py", line 504, in run
    return self.body()
[2023-04-24 19:11:52,441: WARNING/MainProcess]   File "C:\Users\User\AppData\Local\Programs\Python\Python311\Lib\site-packages\billiard\pool.py", line 899, in body
    for _ in self._process_result(1.0):  # blocking
[2023-04-24 19:11:52,441: WARNING/MainProcess]   File "C:\Users\User\AppData\Local\Programs\Python\Python311\Lib\site-packages\billiard\pool.py", line 878, in _process_result
    on_state_change(task)
[2023-04-24 19:11:52,441: WARNING/MainProcess]   File "C:\Users\User\AppData\Local\Programs\Python\Python311\Lib\site-packages\billiard\pool.py", line 853, in on_state_change
    state_handlers[state](*args)
[2023-04-24 19:11:52,441: WARNING/MainProcess]   File "C:\Users\User\AppData\Local\Programs\Python\Python311\Lib\site-packages\billiard\pool.py", line 835, in on_ready
    item._set(i, obj)
[2023-04-24 19:11:52,441: WARNING/MainProcess]   File "C:\Users\User\AppData\Local\Programs\Python\Python311\Lib\site-packages\billiard\pool.py", line 1828, in _set
    self.safe_apply_callback(
[2023-04-24 19:11:52,441: WARNING/MainProcess]   File "C:\Users\User\AppData\Local\Programs\Python\Python311\Lib\site-packages\billiard\pool.py", line 1796, in safe_apply_callback
    fun(*args, **kwargs)
[2023-04-24 19:11:52,441: WARNING/MainProcess]   File "C:\Users\User\AppData\Local\Programs\Python\Python311\Lib\site-packages\celery\worker\request.py", line 596, in on_failure
    error('Task handler raised error: %r', exc,
[2023-04-24 19:11:52,441: WARNING/MainProcess] Message: 'Task handler raised error: %r'
Arguments: (ValueError('not enough values to unpack (expected 3, got 0)'),)
[2023-04-24 19:13:45,942: INFO/MainProcess] Task base.tasks.send_the_email[75b35025-bdda-4e6a-82ee-5985317cbc11] received
[2023-04-24 19:13:45,943: WARNING/MainProcess] --- Logging error ---
[2023-04-24 19:13:45,944: WARNING/MainProcess] Traceback (most recent call last):
[2023-04-24 19:13:45,944: WARNING/MainProcess]   File "C:\Users\User\AppData\Local\Programs\Python\Python311\Lib\logging\__init__.py", line 1110, in emit
    msg = self.format(record)
          ^^^^^^^^^^^^^^^^^^^
[2023-04-24 19:13:45,944: WARNING/MainProcess]   File "C:\Users\User\AppData\Local\Programs\Python\Python311\Lib\logging\__init__.py", line 953, in format
    return fmt.format(record)
           ^^^^^^^^^^^^^^^^^^
[2023-04-24 19:13:45,945: WARNING/MainProcess]   File "C:\Users\User\AppData\Local\Programs\Python\Python311\Lib\site-packages\celery\utils\log.py", line 146, in format
    msg = super().format(record)
          ^^^^^^^^^^^^^^^^^^^^^^
[2023-04-24 19:13:45,945: WARNING/MainProcess]   File "C:\Users\User\AppData\Local\Programs\Python\Python311\Lib\logging\__init__.py", line 695, in format
    record.exc_text = self.formatException(record.exc_info)
                      ^^^^^^^^^^^^^^^^^^^^^^^^^^^^^^^^^^^^^
[2023-04-24 19:13:45,945: WARNING/MainProcess]   File "C:\Users\User\AppData\Local\Programs\Python\Python311\Lib\site-packages\celery\utils\log.py", line 142, in formatException
    r = super().formatException(ei)
        ^^^^^^^^^^^^^^^^^^^^^^^^^^^
[2023-04-24 19:13:45,947: WARNING/MainProcess]   File "C:\Users\User\AppData\Local\Programs\Python\Python311\Lib\logging\__init__.py", line 645, in formatException
    traceback.print_exception(ei[0], ei[1], tb, None, sio)
[2023-04-24 19:13:45,947: WARNING/MainProcess]   File "C:\Users\User\AppData\Local\Programs\Python\Python311\Lib\traceback.py", line 124, in print_exception
    te = TracebackException(type(value), value, tb, limit=limit, compact=True)
         ^^^^^^^^^^^^^^^^^^^^^^^^^^^^^^^^^^^^^^^^^^^^^^^^^^^^^^^^^^^^^^^^^^^^^
[2023-04-24 19:13:45,947: WARNING/MainProcess]   File "C:\Users\User\AppData\Local\Programs\Python\Python311\Lib\traceback.py", line 690, in __init__
    self.stack = StackSummary._extract_from_extended_frame_gen(
                 ^^^^^^^^^^^^^^^^^^^^^^^^^^^^^^^^^^^^^^^^^^^^^^
[2023-04-24 19:13:45,947: WARNING/MainProcess]   File "C:\Users\User\AppData\Local\Programs\Python\Python311\Lib\traceback.py", line 416, in _extract_from_extended_frame_gen
    for f, (lineno, end_lineno, colno, end_colno) in frame_gen:
[2023-04-24 19:13:45,947: WARNING/MainProcess]   File "C:\Users\User\AppData\Local\Programs\Python\Python311\Lib\traceback.py", line 353, in _walk_tb_with_full_positions
    positions = _get_code_position(tb.tb_frame.f_code, tb.tb_lasti)
                ^^^^^^^^^^^^^^^^^^^^^^^^^^^^^^^^^^^^^^^^^^^^^^^^^^^
[2023-04-24 19:13:45,947: WARNING/MainProcess]   File "C:\Users\User\AppData\Local\Programs\Python\Python311\Lib\traceback.py", line 366, in _get_code_position
    positions_gen = code.co_positions()
                    ^^^^^^^^^^^^^^^^^
[2023-04-24 19:13:45,947: WARNING/MainProcess] AttributeError: '_Code' object has no attribute 'co_positions'
[2023-04-24 19:13:45,948: WARNING/MainProcess] Call stack:
[2023-04-24 19:13:45,948: WARNING/MainProcess]   File "C:\Users\User\AppData\Local\Programs\Python\Python311\Lib\threading.py", line 995, in _bootstrap
    self._bootstrap_inner()
[2023-04-24 19:13:45,948: WARNING/MainProcess]   File "C:\Users\User\AppData\Local\Programs\Python\Python311\Lib\threading.py", line 1038, in _bootstrap_inner
    self.run()
[2023-04-24 19:13:45,948: WARNING/MainProcess]   File "C:\Users\User\AppData\Local\Programs\Python\Python311\Lib\site-packages\billiard\pool.py", line 504, in run
    return self.body()
[2023-04-24 19:13:45,948: WARNING/MainProcess]   File "C:\Users\User\AppData\Local\Programs\Python\Python311\Lib\site-packages\billiard\pool.py", line 899, in body
    for _ in self._process_result(1.0):  # blocking
[2023-04-24 19:13:45,950: WARNING/MainProcess]   File "C:\Users\User\AppData\Local\Programs\Python\Python311\Lib\site-packages\billiard\pool.py", line 878, in _process_result
    on_state_change(task)
[2023-04-24 19:13:45,950: WARNING/MainProcess]   File "C:\Users\User\AppData\Local\Programs\Python\Python311\Lib\site-packages\billiard\pool.py", line 853, in on_state_change
    state_handlers[state](*args)
[2023-04-24 19:13:45,950: WARNING/MainProcess]   File "C:\Users\User\AppData\Local\Programs\Python\Python311\Lib\site-packages\billiard\pool.py", line 835, in on_ready
    item._set(i, obj)
[2023-04-24 19:13:45,950: WARNING/MainProcess]   File "C:\Users\User\AppData\Local\Programs\Python\Python311\Lib\site-packages\billiard\pool.py", line 1828, in _set
    self.safe_apply_callback(
[2023-04-24 19:13:45,950: WARNING/MainProcess]   File "C:\Users\User\AppData\Local\Programs\Python\Python311\Lib\site-packages\billiard\pool.py", line 1796, in safe_apply_callback
    fun(*args, **kwargs)
[2023-04-24 19:13:45,950: WARNING/MainProcess]   File "C:\Users\User\AppData\Local\Programs\Python\Python311\Lib\site-packages\celery\worker\request.py", line 596, in on_failure
    error('Task handler raised error: %r', exc,
[2023-04-24 19:13:45,950: WARNING/MainProcess] Message: 'Task handler raised error: %r'
Arguments: (ValueError('not enough values to unpack (expected 3, got 0)'),)
